Workbook

Sheet Cover
B2: HOTEL DCF SENSITIVITY ANALYSIS MODEL
B3: Development-Stage Hotel | 5/8/10/12/20-Year Holding Period Comparison
B5: MODEL OVERVIEW
B7: This model evaluates a development-stage hotel investment under five holding-period scenarios
B8: (5, 8, 10, 12, and 20 years) using a fully formula-driven 20-year unlevered DCF.
B10: All operating assumptions, growth rates, discount rates, exit caps, and renovation cycles are
B11: adjustable via the Inputs sheet. Sensitivity tables and charts update automatically.
B14: WORKBOOK MAP
B16: 1. Inputs | C16: All adjustable assumptions — discount rate, growth, exit cap, renovation cycle
B17: 2. CashFlow_20Y | C17: Full 20-year P&L: revenue, NOI, FF&E reserve, renovation capex, unlevered FCF
B18: 3. Scenarios | C18: Parallel DCFs for each holding period with terminal value & IRR
B19: 4. Sensitivity | C19: 2-way data tables: NPV/IRR vs. discount rate × exit cap rate
B20: 5. Summary | C20: Side-by-side comparison: NPV, IRR, Equity Multiple, Payback
B21: 6. Charts | C21: NPV bar chart, IRR comparison, cumulative cash flow lines
B22: 7. Methodology | C22: Formulas, hospitality benchmarks, and model conventions
B25: COLOR LEGEND
B27: 0.075 | C27: User-editable assumption (blue text, yellow fill)
B28: Formula | C28: Calculated by the model (do not overwrite)
B29: Output | C29: Key result (NPV, IRR, multiples)

Sheet Inputs
B2: INPUTS & ASSUMPTIONS
B3: All blue/yellow cells are editable. Outputs flow to Cash Flow, Scenarios, Sensitivity & Summary.
B5: PROPERTY PROFILE
B6: Number of Keys (Rooms) | C6: 35
B7: Property Type | C7: Ultra-Luxury Boutique (35 keys)
B8: Development / Stabilization Period (yrs) | C8: 3
B9: Stabilized Occupancy | C9: =VLOOKUP($C$46,$B$49:$E$51,3,FALSE()) -> 0.62
B10: Stabilized ADR ($) | C10: =VLOOKUP($C$46,$B$49:$E$51,2,FALSE()) -> 4200
B11: F&B Revenue (% of Rooms Rev) | C11: 0.4
B12: Other Revenue (% of Rooms Rev) | C12: 0.12
B14: DEVELOPMENT-STAGE RAMP-UP
B15: Year of Operation | C15: Year 1 (Opening) | D15: Year 2 | E15: Year 3 (Stabilization) | F15: Year 4+ (Stabilized)
B16: Occupancy % of Stabilized | C16: 0.5 | D16: 0.7 | E16: 0.88 | F16: 1
B17: ADR % of Stabilized | C17: 0.75 | D17: 0.85 | E17: 0.95 | F17: 1
B19: OPERATING MARGINS & EXPENSES
B20: Departmental Expenses (% of Total Rev) | C20: 0.36
B21: Undistributed Operating Expenses (% Rev) | C21: 0.2
B22: Property Taxes & Insurance (% Rev) | C22: 0.03
B23: Management Fee (% Rev) | C23: 0.035
B24: FF&E Reserve (% Rev) | C24: 0.045
B26: GROWTH RATES (post-stabilization)
B27: ADR Growth Rate (annual) | C27: 0.035
B28: Occupancy Drift (annual, +/-) | C28: 0
B29: F&B / Other Revenue Growth | C29: 0.03
B30: Operating Expense Inflation | C30: 0.03
B32: CAPITAL STRUCTURE & RENOVATION
B33: Total Development Cost ($, all-in) | C33: 42000000
B34: Discount Rate (Unlevered) | C34: 0.095
B35: Terminal Cap Rate (Exit Cap) | C35: 0.075
B36: Selling Costs (% of Sale Price) | C36: 0.02
B37: Renovation Cycle (years) | C37: 8
B38: Renovation Capex (% of Annual Revenue) | C38: 0.12
B39: PIP Renovation in Year (set 0 if none) | C39: 0
B41: HOLDING PERIOD SCENARIOS
B42: Scenario | C42: Short | D42: Medium-Short | E42: Standard | F42: Medium-Long | G42: Long
B43: Holding Period (years) | C43: 5 | D43: 8 | E43: 10 | F43: 12 | G43: 20
B45: OPERATING SCENARIO SWITCHER
B46: Active Scenario (Upside / Base / Stress) | C46: Base
B48: Scenario | C48: Stabilized ADR ($) | D48: Stabilized Occupancy | E48: Stabilized RevPAR ($) | F48: Source / Anchor Comp
B49: Upside | C49: 5000 | D49: 0.65 | E49: =C49*D49 -> 3250 | F49: Brando high season ($5,900) less 15%; Amanyara peak
...

Sheet CashFlow_20Y
B2: 20-YEAR CASH FLOW PROJECTION
B3: Unlevered free cash flow with development ramp & periodic renovation capex
B5: Line Item | C5: Year 1 | D5: Year 2 | E5: Year 3 | F5: Year 4 | G5: Year 5 | H5: Year 6 | I5: Year 7 | J5: Year 8 | K5: Year 9 | L5: Year 10 | M5: Year 11 | N5: Year 12 | O5: Year 13 | P5: Year 14 | Q5: Year 15 | R5: Year 16 | S5: Year 17 | T5: Year 18 | U5: Year 19 | V5: Year 20
B6: Year # | C6: 1 | D6: 2 | E6: 3 | F6: 4 | G6: 5 | H6: 6 | I6: 7 | J6: 8 | K6: 9 | L6: 10 | M6: 11 | N6: 12 | O6: 13 | P6: 14 | Q6: 15 | R6: 16 | S6: 17 | T6: 18 | U6: 19 | V6: 20
B8: OPERATING ASSUMPTIONS
B9: Occupancy % | C9: =Inputs!$C$9*INDEX(Inputs!$C$16:$F$16,1,1) -> 0.31 | D9: =Inputs!$C$9*INDEX(Inputs!$C$16:$F$16,1,2) -> 0.434 | E9: =Inputs!$C$9*INDEX(Inputs!$C$16:$F$16,1,3) -> 0.5456 | F9: =Inputs!$C$9*Inputs!$F$16 -> 0.62 | G9: =F9*(1+Inputs!$C$28) -> 0.62 | H9: =G9*(1+Inputs!$C$28) -> 0.62 | I9: =H9*(1+Inputs!$C$28) -> 0.62 | J9: =I9*(1+Inputs!$C$28) -> 0.62 | K9: =J9*(1+Inputs!$C$28) -> 0.62 | L9: =K9*(1+Inputs!$C$28) -> 0.62 | M9: =L9*(1+Inputs!$C$28) -> 0.62 | N9: =M9*(1+Inputs!$C$28) -> 0.62 | ... V9: =U9*(1+Inputs!$C$28) -> 0.62
B10: ADR ($) | C10: =Inputs!$C$10*INDEX(Inputs!$C$17:$F$17,1,1) -> 3150 | D10: =Inputs!$C$10*INDEX(Inputs!$C$17:$F$17,1,2) -> 3570 | E10: =Inputs!$C$10*INDEX(Inputs!$C$17:$F$17,1,3) -> 3990 | F10: =Inputs!$C$10*Inputs!$F$17 -> 4200 | G10: =F10*(1+Inputs!$C$27) -> 4347 | H10: =G10*(1+Inputs!$C$27) -> 4499.145 | I10: =H10*(1+Inputs!$C$27) -> 4656.6151 | J10: =I10*(1+Inputs!$C$27) -> 4819.5966 | K10: =J10*(1+Inputs!$C$27) -> 4988.2825 | L10: =K10*(1+Inputs!$C$27) -> 5162.8724 | M10: =L10*(1+Inputs!$C$27) -> 5343.5729 | N10: =M10*(1+Inputs!$C$27) -> 5530.598 | ... V10: =U10*(1+Inputs!$C$27) -> 7282.7414
B11: RevPAR ($) | C11: =C9*C10 -> 976.5 | D11: =D9*D10 -> 1549.38 | E11: =E9*E10 -> 2176.944 | F11: =F9*F10 -> 2604 | G11: =G9*G10 -> 2695.14 | H11: =H9*H10 -> 2789.4699 | I11: =I9*I10 -> 2887.1013 | J11: =J9*J10 -> 2988.1499 | ... V11: =V9*V10 -> 4515.2996
B13: REVENUE
B14: Rooms Revenue | C14: =C11*Inputs!$C$6*365 -> 12474788 | D14: =D11*Inputs!$C$6*365 -> 19793330 | E14: =E11*Inputs!$C$6*365 -> 27810460 | F14: =F11*Inputs!$C$6*365 -> 33266100 | G14: =G11*Inputs!$C$6*365 -> 34430414 | H14: =H11*Inputs!$C$6*365 -> 35635478 | I14: =I11*Inputs!$C$6*365 -> 36882720 | J14: =J11*Inputs!$C$6*365 -> 38173615 | ... V14: =V11*Inputs!$C$6*365 -> 57682953
B15: F&B Revenue | C15: =C14*Inputs!$C$11 -> 4989915 | D15: =IF(2=1,D14*Inputs!$C$11,C15*(1+Inputs!$C$29)) -> 5139612.5 | E15: =IF(3=1,E14*Inputs!$C$11,D15*(1+Inputs!$C$29)) -> 5293800.8 | F15: =IF(4=1,F14*Inputs!$C$11,E15*(1+Inputs!$C$29)) -> 5452614.8 | G15: =IF(5=1,G14*Inputs!$C$11,F15*(1+Inputs!$C$29)) -> 5616193.3 | H15: =IF(6=1,H14*Inputs!$C$11,G15*(1+Inputs!$C$29)) -> 5784679.1 | I15: =IF(7=1,I14*Inputs!$C$11,H15*(1+Inputs!$C$29)) -> 5958219.5 | J15: =IF(8=1,J14*Inputs!$C$11,I15*(1+Inputs!$C$29)) -> 6136966 | K15: =IF(9=1,K14*Inputs!$C$11,J15*(1+Inputs!$C$29)) -> 6321075 | L15: =IF(10=1,L14*Inputs!$C$11,K15*(1+Inputs!$C$29)) -> 6510707.3 | M15: =IF(11=1,M14*Inputs!$C$11,L15*(1+Inputs!$C$29)) -> 6706028.5 | N15: =IF(12=1,N14*Inputs!$C$11,M15*(1+Inputs!$C$29)) -> 6907209.4 | O15: =IF(13=1,O14*Inputs!$C$11,N15*(1+Inputs!$C$29)) -> 7114425.6 | P15: =IF(14=1,P14*Inputs!$C$11,O15*(1+Inputs!$C$29)) -> 7327858.4 | Q15: =IF(15=1,Q14*Inputs!$C$11,P15*(1+Inputs!$C$29)) -> 7547694.2 | R15: =IF(16=1,R14*Inputs!$C$11,Q15*(1+Inputs!$C$29)) -> 7774125 | S15: =IF(17=1,S14*Inputs!$C$11,R15*(1+Inputs!$C$29)) -> 8007348.7 | T15: =IF(18=1,T14*Inputs!$C$11,S15*(1+Inputs!$C$29)) -> 8247569.2 | U15: =IF(19=1,U14*Inputs!$C$11,T15*(1+Inputs!$C$29)) -> 8494996.3 | V15: =IF(20=1,V14*Inputs!$C$11,U15*(1+Inputs!$C$29)) -> 8749846.2
B16: Other Revenue | C16: =IF(1=1,C14*Inputs!$C$12,B16*(1+Inputs!$C$29)) -> 1496974.5 | D16: =IF(2=1,D14*Inputs!$C$12,C16*(1+Inputs!$C$29)) -> 1541883.7 | E16: =IF(3=1,E14*Inputs!$C$12,D16*(1+Inputs!$C$29)) -> 1588140.2 | F16: =IF(4=1,F14*Inputs!$C$12,E16*(1+Inputs!$C$29)) -> 1635784.5 | G16: =IF(5=1,G14*Inputs!$C$12,F16*(1+Inputs!$C$29)) -> 1684858 | H16: =IF(6=1,H14*Inputs!$C$12,G16*(1+Inputs!$C$29)) -> 1735403.7 | I16: =IF(7=1,I14*Inputs!$C$12,H16*(1+Inputs!$C$29)) -> 1787465.8 | J16: =IF(8=1,J14*Inputs!$C$12,I16*(1+Inputs!$C$29)) -> 1841089.8 | K16: =IF(9=1,K14*Inputs!$C$12,J16*(1+Inputs!$C$29)) -> 1896322.5 | L16: =IF(10=1,L14*Inputs!$C$12,K16*(1+Inputs!$C$29)) -> 1953212.2 | M16: =IF(11=1,M14*Inputs!$C$12,L16*(1+Inputs!$C$29)) -> 2011808.6 | N16: =IF(12=1,N14*Inputs!$C$12,M16*(1+Inputs!$C$29)) -> 2072162.8 | O16: =IF(13=1,O14*Inputs!$C$12,N16*(1+Inputs!$C$29)) -> 2134327.7 | P16: =IF(14=1,P14*Inputs!$C$12,O16*(1+Inputs!$C$29)) -> 2198357.5 | Q16: =IF(15=1,Q14*Inputs!$C$12,P16*(1+Inputs!$C$29)) -> 2264308.2 | R16: =IF(16=1,R14*Inputs!$C$12,Q16*(1+Inputs!$C$29)) -> 2332237.5 | S16: =IF(17=1,S14*Inputs!$C$12,R16*(1+Inputs!$C$29)) -> 2402204.6 | T16: =IF(18=1,T14*Inputs!$C$12,S16*(1+Inputs!$C$29)) -> 2474270.8 | U16: =IF(19=1,U14*Inputs!$C$12,T16*(1+Inputs!$C$29)) -> 2548498.9 | V16: =IF(20=1,V14*Inputs!$C$12,U16*(1+Inputs!$C$29)) -> 2624953.8
B17: Total Revenue | C17: =SUM(C14:C16) -> 18961677 | D17: =SUM(D14:D16) -> 26474826 | E17: =SUM(E14:E16) -> 34692401 | F17: =SUM(F14:F16) -> 40354499 | G17: =SUM(G14:G16) -> 41731465 | H17: =SUM(H14:H16) -> 43155561 | I17: =SUM(I14:I16) -> 44628405 | J17: =SUM(J14:J16) -> 46151671 | ... V17: =SUM(V14:V16) -> 69057753
B19: OPERATING EXPENSES
B20: Departmental Expenses | C20: =C17*Inputs!$C$20*((1+Inputs!$C$30)/(1+Inputs!$C$27))^MAX(0,1-4) -> 6826203.7 | D20: =D17*Inputs!$C$20*((1+Inputs!$C$30)/(1+Inputs!$C$27))^MAX(0,2-4) -> 9530937.2 | E20: =E17*Inputs!$C$20*((1+Inputs!$C$30)/(1+Inputs!$C$27))^MAX(0,3-4) -> 12489264 | F20: =F17*Inputs!$C$20*((1+Inputs!$C$30)/(1+Inputs!$C$27))^MAX(0,4-4) -> 14527620 | G20: =G17*Inputs!$C$20*((1+Inputs!$C$30)/(1+Inputs!$C$27))^MAX(0,5-4) -> 14950751 | H20: =H17*Inputs!$C$20*((1+Inputs!$C$30)/(1+Inputs!$C$27))^MAX(0,6-4) -> 15386258 | I20: =I17*Inputs!$C$20*((1+Inputs!$C$30)/(1+Inputs!$C$27))^MAX(0,7-4) -> 15834505 | J20: =J17*Inputs!$C$20*((1+Inputs!$C$30)/(1+Inputs!$C$27))^MAX(0,8-4) -> 16295865 | K20: =K17*Inputs!$C$20*((1+Inputs!$C$30)/(1+Inputs!$C$27))^MAX(0,9-4) -> 16770724 | L20: =L17*Inputs!$C$20*((1+Inputs!$C$30)/(1+Inputs!$C$27))^MAX(0,10-4) -> 17259478 | M20: =M17*Inputs!$C$20*((1+Inputs!$C$30)/(1+Inputs!$C$27))^MAX(0,11-4) -> 17762535 | N20: =N17*Inputs!$C$20*((1+Inputs!$C$30)/(1+Inputs!$C$27))^MAX(0,12-4) -> 18280316 | O20: =O17*Inputs!$C$20*((1+Inputs!$C$30)/(1+Inputs!$C$27))^MAX(0,13-4) -> 18813252 | P20: =P17*Inputs!$C$20*((1+Inputs!$C$30)/(1+Inputs!$C$27))^MAX(0,14-4) -> 19361788 | Q20: =Q17*Inputs!$C$20*((1+Inputs!$C$30)/(1+Inputs!$C$27))^MAX(0,15-4) -> 19926384 | R20: =R17*Inputs!$C$20*((1+Inputs!$C$30)/(1+Inputs!$C$27))^MAX(0,16-4) -> 20507511 | S20: =S17*Inputs!$C$20*((1+Inputs!$C$30)/(1+Inputs!$C$27))^MAX(0,17-4) -> 21105655 | T20: =T17*Inputs!$C$20*((1+Inputs!$C$30)/(1+Inputs!$C$27))^MAX(0,18-4) -> 21721316 | U20: =U17*Inputs!$C$20*((1+Inputs!$C$30)/(1+Inputs!$C$27))^MAX(0,19-4) -> 22355008 | V20: =V17*Inputs!$C$20*((1+Inputs!$C$30)/(1+Inputs!$C$27))^MAX(0,20-4) -> 23007262
B21: Undistributed Operating Exp. | C21: =C17*Inputs!$C$21*((1+Inputs!$C$30)/(1+Inputs!$C$27))^MAX(0,1-4) -> 3792335.4 | D21: =D17*Inputs!$C$21*((1+Inputs!$C$30)/(1+Inputs!$C$27))^MAX(0,2-4) -> 5294965.1 | E21: =E17*Inputs!$C$21*((1+Inputs!$C$30)/(1+Inputs!$C$27))^MAX(0,3-4) -> 6938480.1 | F21: =F17*Inputs!$C$21*((1+Inputs!$C$30)/(1+Inputs!$C$27))^MAX(0,4-4) -> 8070899.9 | G21: =G17*Inputs!$C$21*((1+Inputs!$C$30)/(1+Inputs!$C$27))^MAX(0,5-4) -> 8305972.7 | H21: =H17*Inputs!$C$21*((1+Inputs!$C$30)/(1+Inputs!$C$27))^MAX(0,6-4) -> 8547921.2 | I21: =I17*Inputs!$C$21*((1+Inputs!$C$30)/(1+Inputs!$C$27))^MAX(0,7-4) -> 8796947.2 | J21: =J17*Inputs!$C$21*((1+Inputs!$C$30)/(1+Inputs!$C$27))^MAX(0,8-4) -> 9053258.5 | K21: =K17*Inputs!$C$21*((1+Inputs!$C$30)/(1+Inputs!$C$27))^MAX(0,9-4) -> 9317069.1 | L21: =L17*Inputs!$C$21*((1+Inputs!$C$30)/(1+Inputs!$C$27))^MAX(0,10-4) -> 9588599.1 | M21: =M17*Inputs!$C$21*((1+Inputs!$C$30)/(1+Inputs!$C$27))^MAX(0,11-4) -> 9868075.3 | N21: =N17*Inputs!$C$21*((1+Inputs!$C$30)/(1+Inputs!$C$27))^MAX(0,12-4) -> 10155731 | O21: =O17*Inputs!$C$21*((1+Inputs!$C$30)/(1+Inputs!$C$27))^MAX(0,13-4) -> 10451806 | P21: =P17*Inputs!$C$21*((1+Inputs!$C$30)/(1+Inputs!$C$27))^MAX(0,14-4) -> 10756549 | Q21: =Q17*Inputs!$C$21*((1+Inputs!$C$30)/(1+Inputs!$C$27))^MAX(0,15-4) -> 11070214 | R21: =R17*Inputs!$C$21*((1+Inputs!$C$30)/(1+Inputs!$C$27))^MAX(0,16-4) -> 11393062 | S21: =S17*Inputs!$C$21*((1+Inputs!$C$30)/(1+Inputs!$C$27))^MAX(0,17-4) -> 11725364 | T21: =T17*Inputs!$C$21*((1+Inputs!$C$30)/(1+Inputs!$C$27))^MAX(0,18-4) -> 12067398 | U21: =U17*Inputs!$C$21*((1+Inputs!$C$30)/(1+Inputs!$C$27))^MAX(0,19-4) -> 12419449 | V21: =V17*Inputs!$C$21*((1+Inputs!$C$30)/(1+Inputs!$C$27))^MAX(0,20-4) -> 12781812
B22: Property Taxes & Insurance | C22: =C17*Inputs!$C$22*((1+Inputs!$C$30)/(1+Inputs!$C$27))^MAX(0,1-4) -> 568850.31 | D22: =D17*Inputs!$C$22*((1+Inputs!$C$30)/(1+Inputs!$C$27))^MAX(0,2-4) -> 794244.77 | E22: =E17*Inputs!$C$22*((1+Inputs!$C$30)/(1+Inputs!$C$27))^MAX(0,3-4) -> 1040772 | F22: =F17*Inputs!$C$22*((1+Inputs!$C$30)/(1+Inputs!$C$27))^MAX(0,4-4) -> 1210635 | G22: =G17*Inputs!$C$22*((1+Inputs!$C$30)/(1+Inputs!$C$27))^MAX(0,5-4) -> 1245895.9 | H22: =H17*Inputs!$C$22*((1+Inputs!$C$30)/(1+Inputs!$C$27))^MAX(0,6-4) -> 1282188.2 | I22: =I17*Inputs!$C$22*((1+Inputs!$C$30)/(1+Inputs!$C$27))^MAX(0,7-4) -> 1319542.1 | J22: =J17*Inputs!$C$22*((1+Inputs!$C$30)/(1+Inputs!$C$27))^MAX(0,8-4) -> 1357988.8 | K22: =K17*Inputs!$C$22*((1+Inputs!$C$30)/(1+Inputs!$C$27))^MAX(0,9-4) -> 1397560.4 | L22: =L17*Inputs!$C$22*((1+Inputs!$C$30)/(1+Inputs!$C$27))^MAX(0,10-4) -> 1438289.9 | M22: =M17*Inputs!$C$22*((1+Inputs!$C$30)/(1+Inputs!$C$27))^MAX(0,11-4) -> 1480211.3 | N22: =N17*Inputs!$C$22*((1+Inputs!$C$30)/(1+Inputs!$C$27))^MAX(0,12-4) -> 1523359.6 | O22: =O17*Inputs!$C$22*((1+Inputs!$C$30)/(1+Inputs!$C$27))^MAX(0,13-4) -> 1567771 | P22: =P17*Inputs!$C$22*((1+Inputs!$C$30)/(1+Inputs!$C$27))^MAX(0,14-4) -> 1613482.4 | Q22: =Q17*Inputs!$C$22*((1+Inputs!$C$30)/(1+Inputs!$C$27))^MAX(0,15-4) -> 1660532 | R22: =R17*Inputs!$C$22*((1+Inputs!$C$30)/(1+Inputs!$C$27))^MAX(0,16-4) -> 1708959.3 | S22: =S17*Inputs!$C$22*((1+Inputs!$C$30)/(1+Inputs!$C$27))^MAX(0,17-4) -> 1758804.6 | T22: =T17*Inputs!$C$22*((1+Inputs!$C$30)/(1+Inputs!$C$27))^MAX(0,18-4) -> 1810109.7 | U22: =U17*Inputs!$C$22*((1+Inputs!$C$30)/(1+Inputs!$C$27))^MAX(0,19-4) -> 1862917.4 | V22: =V17*Inputs!$C$22*((1+Inputs!$C$30)/(1+Inputs!$C$27))^MAX(0,20-4) -> 1917271.9
B23: Management Fee | C23: =C17*Inputs!$C$23 -> 663658.69 | D23: =D17*Inputs!$C$23 -> 926618.9 | E23: =E17*Inputs!$C$23 -> 1214234 | F23: =F17*Inputs!$C$23 -> 1412407.5 | G23: =G17*Inputs!$C$23 -> 1460601.3 | H23: =H17*Inputs!$C$23 -> 1510444.6 | I23: =I17*Inputs!$C$23 -> 1561994.2 | J23: =J17*Inputs!$C$23 -> 1615308.5 | ... V23: =V17*Inputs!$C$23 -> 2417021.4
B24: Total Operating Expenses | C24: =SUM(C20:C23) -> 11851048 | D24: =SUM(D20:D23) -> 16546766 | E24: =SUM(E20:E23) -> 21682750 | F24: =SUM(F20:F23) -> 25221562 | G24: =SUM(G20:G23) -> 25963221 | H24: =SUM(H20:H23) -> 26726812 | I24: =SUM(I20:I23) -> 27512988 | J24: =SUM(J20:J23) -> 28322421 | ... V24: =SUM(V20:V23) -> 40123368
B26: NET OPERATING INCOME (NOI) | C26: =C17-C24 -> 7110628.9 | D26: =D17-D24 -> 9928059.6 | E26: =E17-E24 -> 13009650 | F26: =F17-F24 -> 15132937 | G26: =G17-G24 -> 15768244 | H26: =H17-H24 -> 16428749 | I26: =I17-I24 -> 17115417 | J26: =J17-J24 -> 17829250 | ... V26: =V17-V24 -> 28934385
B27: NOI Margin % | C27: =C26/C17 -> 0.375 | D27: =D26/D17 -> 0.375 | E27: =E26/E17 -> 0.375 | F27: =F26/F17 -> 0.375 | G27: =G26/G17 -> 0.37785024 | H27: =H26/H17 -> 0.38068671 | I27: =I26/I17 -> 0.38350948 | J27: =J26/J17 -> 0.38631862 | ... V27: =V26/V17 -> 0.41898822
B29: CAPITAL EXPENDITURES
B30: FF&E Reserve | C30: =C17*Inputs!$C$24 -> 853275.46 | D30: =D17*Inputs!$C$24 -> 1191367.2 | E30: =E17*Inputs!$C$24 -> 1561158 | F30: =F17*Inputs!$C$24 -> 1815952.5 | G30: =G17*Inputs!$C$24 -> 1877915.9 | H30: =H17*Inputs!$C$24 -> 1942000.2 | I30: =I17*Inputs!$C$24 -> 2008278.2 | J30: =J17*Inputs!$C$24 -> 2076825.2 | ... V30: =V17*Inputs!$C$24 -> 3107598.9
B31: Renovation Capex (cycle) | C31: =IF(OR(AND(Inputs!$C$37>0,MOD(1,Inputs!$C$37)=0,1>=Inputs!$C$8),1=Inputs!$C$39),C17*Inputs!$C$38,0) -> 0 | D31: =IF(OR(AND(Inputs!$C$37>0,MOD(2,Inputs!$C$37)=0,2>=Inputs!$C$8),2=Inputs!$C$39),D17*Inputs!$C$38,0) -> 0 | E31: =IF(OR(AND(Inputs!$C$37>0,MOD(3,Inputs!$C$37)=0,3>=Inputs!$C$8),3=Inputs!$C$39),E17*Inputs!$C$38,0) -> 0 | F31: =IF(OR(AND(Inputs!$C$37>0,MOD(4,Inputs!$C$37)=0,4>=Inputs!$C$8),4=Inputs!$C$39),F17*Inputs!$C$38,0) -> 0 | G31: =IF(OR(AND(Inputs!$C$37>0,MOD(5,Inputs!$C$37)=0,5>=Inputs!$C$8),5=Inputs!$C$39),G17*Inputs!$C$38,0) -> 0 | H31: =IF(OR(AND(Inputs!$C$37>0,MOD(6,Inputs!$C$37)=0,6>=Inputs!$C$8),6=Inputs!$C$39),H17*Inputs!$C$38,0) -> 0 | I31: =IF(OR(AND(Inputs!$C$37>0,MOD(7,Inputs!$C$37)=0,7>=Inputs!$C$8),7=Inputs!$C$39),I17*Inputs!$C$38,0) -> 0 | J31: =IF(OR(AND(Inputs!$C$37>0,MOD(8,Inputs!$C$37)=0,8>=Inputs!$C$8),8=Inputs!$C$39),J17*Inputs!$C$38,0) -> 5538200.5 | K31: =IF(OR(AND(Inputs!$C$37>0,MOD(9,Inputs!$C$37)=0,9>=Inputs!$C$8),9=Inputs!$C$39),K17*Inputs!$C$38,0) -> 0 | L31: =IF(OR(AND(Inputs!$C$37>0,MOD(10,Inputs!$C$37)=0,10>=Inputs!$C$8),10=Inputs!$C$39),L17*Inputs!$C$38,0) -> 0 | M31: =IF(OR(AND(Inputs!$C$37>0,MOD(11,Inputs!$C$37)=0,11>=Inputs!$C$8),11=Inputs!$C$39),M17*Inputs!$C$38,0) -> 0 | N31: =IF(OR(AND(Inputs!$C$37>0,MOD(12,Inputs!$C$37)=0,12>=Inputs!$C$8),12=Inputs!$C$39),N17*Inputs!$C$38,0) -> 0 | O31: =IF(OR(AND(Inputs!$C$37>0,MOD(13,Inputs!$C$37)=0,13>=Inputs!$C$8),13=Inputs!$C$39),O17*Inputs!$C$38,0) -> 0 | P31: =IF(OR(AND(Inputs!$C$37>0,MOD(14,Inputs!$C$37)=0,14>=Inputs!$C$8),14=Inputs!$C$39),P17*Inputs!$C$38,0) -> 0 | Q31: =IF(OR(AND(Inputs!$C$37>0,MOD(15,Inputs!$C$37)=0,15>=Inputs!$C$8),15=Inputs!$C$39),Q17*Inputs!$C$38,0) -> 0 | R31: =IF(OR(AND(Inputs!$C$37>0,MOD(16,Inputs!$C$37)=0,16>=Inputs!$C$8),16=Inputs!$C$39),R17*Inputs!$C$38,0) -> 7244846.8 | S31: =IF(OR(AND(Inputs!$C$37>0,MOD(17,Inputs!$C$37)=0,17>=Inputs!$C$8),17=Inputs!$C$39),S17*Inputs!$C$38,0) -> 0 | T31: =IF(OR(AND(Inputs!$C$37>0,MOD(18,Inputs!$C$37)=0,18>=Inputs!$C$8),18=Inputs!$C$39),T17*Inputs!$C$38,0) -> 0 | U31: =IF(OR(AND(Inputs!$C$37>0,MOD(19,Inputs!$C$37)=0,19>=Inputs!$C$8),19=Inputs!$C$39),U17*Inputs!$C$38,0) -> 0 | V31: =IF(OR(AND(Inputs!$C$37>0,MOD(20,Inputs!$C$37)=0,20>=Inputs!$C$8),20=Inputs!$C$39),V17*Inputs!$C$38,0) -> 0
B32: Total Capex | C32: =C30+C31 -> 853275.46 | D32: =D30+D31 -> 1191367.2 | E32: =E30+E31 -> 1561158 | F32: =F30+F31 -> 1815952.5 | G32: =G30+G31 -> 1877915.9 | H32: =H30+H31 -> 1942000.2 | I32: =I30+I31 -> 2008278.2 | J32: =J30+J31 -> 7615025.7 | ... V32: =V30+V31 -> 3107598.9
B34: UNLEVERED FREE CASH FLOW | C34: =C26-C32 -> 6257353.4 | D34: =D26-D32 -> 8736692.5 | E34: =E26-E32 -> 11448492 | F34: =F26-F32 -> 13316985 | G34: =G26-G32 -> 13890328 | H34: =H26-H32 -> 14486748 | I34: =I26-I32 -> 15107138 | J34: =J26-J32 -> 10214224 | ... V34: =V26-V32 -> 25826786
B36: Forward NOI (Year N+1, for Exit Value) | C36: =D26 -> 9928059.6 | D36: =E26 -> 13009650 | E36: =F26 -> 15132937 | F36: =G26 -> 15768244 | G36: =H26 -> 16428749 | H36: =I26 -> 17115417 | I36: =J26 -> 17829250 | J36: =K26 -> 18571287 | ... U36: =V26 -> 28934385 | V36: =V26*(1+Inputs!$C$27) -> 29947089

Sheet Scenarios
B2: HOLDING PERIOD SCENARIOS — DCF & EXIT
B3: Each scenario uses the same operating cash flows but exits in a different year.
B5: 5-Year Hold
B6: Period | C6: Y0 | D6: Y1 | E6: Y2 | F6: Y3 | G6: Y4 | H6: Y5 | I6: Y6 | J6: Y7 | K6: Y8 | L6: Y9 | M6: Y10 | N6: Y11 | O6: Y12 | P6: Y13 | Q6: Y14 | R6: Y15 | S6: Y16 | T6: Y17 | U6: Y18 | V6: Y19 | W6: Y20
B7: Operating FCF | C7: =-Inputs!$C$33 -> -42000000 | D7: =IF(1<=5,CashFlow_20Y!C34,0) -> 6257353.4 | E7: =IF(2<=5,CashFlow_20Y!D34,0) -> 8736692.5 | F7: =IF(3<=5,CashFlow_20Y!E34,0) -> 11448492 | G7: =IF(4<=5,CashFlow_20Y!F34,0) -> 13316985 | H7: =IF(5<=5,CashFlow_20Y!G34,0) -> 13890328 | I7: =IF(6<=5,CashFlow_20Y!H34,0) -> 0 | J7: =IF(7<=5,CashFlow_20Y!I34,0) -> 0 | K7: =IF(8<=5,CashFlow_20Y!J34,0) -> 0 | L7: =IF(9<=5,CashFlow_20Y!K34,0) -> 0 | M7: =IF(10<=5,CashFlow_20Y!L34,0) -> 0 | N7: =IF(11<=5,CashFlow_20Y!M34,0) -> 0 | O7: =IF(12<=5,CashFlow_20Y!N34,0) -> 0 | P7: =IF(13<=5,CashFlow_20Y!O34,0) -> 0 | Q7: =IF(14<=5,CashFlow_20Y!P34,0) -> 0 | R7: =IF(15<=5,CashFlow_20Y!Q34,0) -> 0 | S7: =IF(16<=5,CashFlow_20Y!R34,0) -> 0 | T7: =IF(17<=5,CashFlow_20Y!S34,0) -> 0 | U7: =IF(18<=5,CashFlow_20Y!T34,0) -> 0 | V7: =IF(19<=5,CashFlow_20Y!U34,0) -> 0 | W7: =IF(20<=5,CashFlow_20Y!V34,0) -> 0
B8: Terminal Value (net of selling costs) | D8: =IF(1=5,(CashFlow_20Y!C36/Inputs!$C$35)*(1-Inputs!$C$36),0) -> 0 | E8: =IF(2=5,(CashFlow_20Y!D36/Inputs!$C$35)*(1-Inputs!$C$36),0) -> 0 | F8: =IF(3=5,(CashFlow_20Y!E36/Inputs!$C$35)*(1-Inputs!$C$36),0) -> 0 | G8: =IF(4=5,(CashFlow_20Y!F36/Inputs!$C$35)*(1-Inputs!$C$36),0) -> 0 | H8: =IF(5=5,(CashFlow_20Y!G36/Inputs!$C$35)*(1-Inputs!$C$36),0) -> 2.1466898e+08 | I8: =IF(6=5,(CashFlow_20Y!H36/Inputs!$C$35)*(1-Inputs!$C$36),0) -> 0 | J8: =IF(7=5,(CashFlow_20Y!I36/Inputs!$C$35)*(1-Inputs!$C$36),0) -> 0 | K8: =IF(8=5,(CashFlow_20Y!J36/Inputs!$C$35)*(1-Inputs!$C$36),0) -> 0 | L8: =IF(9=5,(CashFlow_20Y!K36/Inputs!$C$35)*(1-Inputs!$C$36),0) -> 0 | M8: =IF(10=5,(CashFlow_20Y!L36/Inputs!$C$35)*(1-Inputs!$C$36),0) -> 0 | N8: =IF(11=5,(CashFlow_20Y!M36/Inputs!$C$35)*(1-Inputs!$C$36),0) -> 0 | O8: =IF(12=5,(CashFlow_20Y!N36/Inputs!$C$35)*(1-Inputs!$C$36),0) -> 0 | P8: =IF(13=5,(CashFlow_20Y!O36/Inputs!$C$35)*(1-Inputs!$C$36),0) -> 0 | Q8: =IF(14=5,(CashFlow_20Y!P36/Inputs!$C$35)*(1-Inputs!$C$36),0) -> 0 | R8: =IF(15=5,(CashFlow_20Y!Q36/Inputs!$C$35)*(1-Inputs!$C$36),0) -> 0 | S8: =IF(16=5,(CashFlow_20Y!R36/Inputs!$C$35)*(1-Inputs!$C$36),0) -> 0 | T8: =IF(17=5,(CashFlow_20Y!S36/Inputs!$C$35)*(1-Inputs!$C$36),0) -> 0 | U8: =IF(18=5,(CashFlow_20Y!T36/Inputs!$C$35)*(1-Inputs!$C$36),0) -> 0 | V8: =IF(19=5,(CashFlow_20Y!U36/Inputs!$C$35)*(1-Inputs!$C$36),0) -> 0 | W8: =IF(20=5,(CashFlow_20Y!V36/Inputs!$C$35)*(1-Inputs!$C$36),0) -> 0
B9: Total Cash Flow | C9: =C7 -> -42000000 | D9: =D7+D8 -> 6257353.4 | E9: =E7+E8 -> 8736692.5 | F9: =F7+F8 -> 11448492 | G9: =G7+G8 -> 13316985 | H9: =H7+H8 -> 2.2855931e+08 | I9: =I7+I8 -> 0 | J9: =J7+J8 -> 0 | K9: =K7+K8 -> 0 | ... W9: =W7+W8 -> 0
B10: Discount Factor | C10: =1/(1+Inputs!$C$34)^0 -> 1 | D10: =1/(1+Inputs!$C$34)^1 -> 0.91324201 | E10: =1/(1+Inputs!$C$34)^2 -> 0.83401097 | F10: =1/(1+Inputs!$C$34)^3 -> 0.76165385 | G10: =1/(1+Inputs!$C$34)^4 -> 0.69557429 | H10: =1/(1+Inputs!$C$34)^5 -> 0.63522767 | I10: =1/(1+Inputs!$C$34)^6 -> 0.58011659 | J10: =1/(1+Inputs!$C$34)^7 -> 0.52978684 | K10: =1/(1+Inputs!$C$34)^8 -> 0.4838236 | L10: =1/(1+Inputs!$C$34)^9 -> 0.44184803 | M10: =1/(1+Inputs!$C$34)^10 -> 0.40351419 | N10: =1/(1+Inputs!$C$34)^11 -> 0.36850611 | O10: =1/(1+Inputs!$C$34)^12 -> 0.33653526 | P10: =1/(1+Inputs!$C$34)^13 -> 0.30733813 | Q10: =1/(1+Inputs!$C$34)^14 -> 0.2806741 | R10: =1/(1+Inputs!$C$34)^15 -> 0.25632337 | S10: =1/(1+Inputs!$C$34)^16 -> 0.23408527 | T10: =1/(1+Inputs!$C$34)^17 -> 0.21377651 | U10: =1/(1+Inputs!$C$34)^18 -> 0.19522969 | V10: =1/(1+Inputs!$C$34)^19 -> 0.17829195 | W10: =1/(1+Inputs!$C$34)^20 -> 0.1628237
B11: PV of Cash Flow | C11: =C9*C10 -> -42000000 | D11: =D9*D10 -> 5714478 | E11: =E9*E10 -> 7286497.3 | F11: =F9*F10 -> 8719788.2 | G11: =G9*G10 -> 9262952.3 | H11: =H9*H10 -> 1.451872e+08 | I11: =I9*I10 -> 0 | J11: =J9*J10 -> 0 | ... W11: =W9*W10 -> 0
B12: Cumulative Cash Flow | C12: =C9 -> -42000000 | D12: =C12+D9 -> -35742647 | E12: =D12+E9 -> -27005954 | F12: =E12+F9 -> -15557462 | G12: =F12+G9 -> -2240477.1 | H12: =G12+H9 -> 2.2631883e+08 | I12: =H12+I9 -> 2.2631883e+08 | J12: =I12+J9 -> 2.2631883e+08 | K12: =J12+K9 -> 2.2631883e+08 | ... W12: =V12+W9 -> 2.2631883e+08
B13: NPV | C13: =SUM(C11:W11) -> 1.3417091e+08
B14: IRR | C14: =IRR(C9:W9) -> 0.51843884
B15: Equity Multiple (Total CF / Initial) | C15: =SUMIF(C9:W9,">0")/(-C9) -> 6.3885436
B16: 8-Year Hold
B17: Period | C17: Y0 | D17: Y1 | E17: Y2 | F17: Y3 | G17: Y4 | H17: Y5 | I17: Y6 | J17: Y7 | K17: Y8 | L17: Y9 | M17: Y10 | N17: Y11 | O17: Y12 | P17: Y13 | Q17: Y14 | R17: Y15 | S17: Y16 | T17: Y17 | U17: Y18 | V17: Y19 | W17: Y20
B18: Operating FCF | C18: =-Inputs!$C$33 -> -42000000 | D18: =IF(1<=8,CashFlow_20Y!C34,0) -> 6257353.4 | E18: =IF(2<=8,CashFlow_20Y!D34,0) -> 8736692.5 | F18: =IF(3<=8,CashFlow_20Y!E34,0) -> 11448492 | G18: =IF(4<=8,CashFlow_20Y!F34,0) -> 13316985 | H18: =IF(5<=8,CashFlow_20Y!G34,0) -> 13890328 | I18: =IF(6<=8,CashFlow_20Y!H34,0) -> 14486748 | J18: =IF(7<=8,CashFlow_20Y!I34,0) -> 15107138 | K18: =IF(8<=8,CashFlow_20Y!J34,0) -> 10214224 | L18: =IF(9<=8,CashFlow_20Y!K34,0) -> 0 | M18: =IF(10<=8,CashFlow_20Y!L34,0) -> 0 | N18: =IF(11<=8,CashFlow_20Y!M34,0) -> 0 | O18: =IF(12<=8,CashFlow_20Y!N34,0) -> 0 | P18: =IF(13<=8,CashFlow_20Y!O34,0) -> 0 | Q18: =IF(14<=8,CashFlow_20Y!P34,0) -> 0 | R18: =IF(15<=8,CashFlow_20Y!Q34,0) -> 0 | S18: =IF(16<=8,CashFlow_20Y!R34,0) -> 0 | T18: =IF(17<=8,CashFlow_20Y!S34,0) -> 0 | U18: =IF(18<=8,CashFlow_20Y!T34,0) -> 0 | V18: =IF(19<=8,CashFlow_20Y!U34,0) -> 0 | W18: =IF(20<=8,CashFlow_20Y!V34,0) -> 0
B19: Terminal Value (net of selling costs) | D19: =IF(1=8,(CashFlow_20Y!C36/Inputs!$C$35)*(1-Inputs!$C$36),0) -> 0 | E19: =IF(2=8,(CashFlow_20Y!D36/Inputs!$C$35)*(1-Inputs!$C$36),0) -> 0 | F19: =IF(3=8,(CashFlow_20Y!E36/Inputs!$C$35)*(1-Inputs!$C$36),0) -> 0 | G19: =IF(4=8,(CashFlow_20Y!F36/Inputs!$C$35)*(1-Inputs!$C$36),0) -> 0 | H19: =IF(5=8,(CashFlow_20Y!G36/Inputs!$C$35)*(1-Inputs!$C$36),0) -> 0 | I19: =IF(6=8,(CashFlow_20Y!H36/Inputs!$C$35)*(1-Inputs!$C$36),0) -> 0 | J19: =IF(7=8,(CashFlow_20Y!I36/Inputs!$C$35)*(1-Inputs!$C$36),0) -> 0 | K19: =IF(8=8,(CashFlow_20Y!J36/Inputs!$C$35)*(1-Inputs!$C$36),0) -> 2.4266482e+08 | L19: =IF(9=8,(CashFlow_20Y!K36/Inputs!$C$35)*(1-Inputs!$C$36),0) -> 0 | M19: =IF(10=8,(CashFlow_20Y!L36/Inputs!$C$35)*(1-Inputs!$C$36),0) -> 0 | N19: =IF(11=8,(CashFlow_20Y!M36/Inputs!$C$35)*(1-Inputs!$C$36),0) -> 0 | O19: =IF(12=8,(CashFlow_20Y!N36/Inputs!$C$35)*(1-Inputs!$C$36),0) -> 0 | P19: =IF(13=8,(CashFlow_20Y!O36/Inputs!$C$35)*(1-Inputs!$C$36),0) -> 0 | Q19: =IF(14=8,(CashFlow_20Y!P36/Inputs!$C$35)*(1-Inputs!$C$36),0) -> 0 | R19: =IF(15=8,(CashFlow_20Y!Q36/Inputs!$C$35)*(1-Inputs!$C$36),0) -> 0 | S19: =IF(16=8,(CashFlow_20Y!R36/Inputs!$C$35)*(1-Inputs!$C$36),0) -> 0 | T19: =IF(17=8,(CashFlow_20Y!S36/Inputs!$C$35)*(1-Inputs!$C$36),0) -> 0 | U19: =IF(18=8,(CashFlow_20Y!T36/Inputs!$C$35)*(1-Inputs!$C$36),0) -> 0 | V19: =IF(19=8,(CashFlow_20Y!U36/Inputs!$C$35)*(1-Inputs!$C$36),0) -> 0 | W19: =IF(20=8,(CashFlow_20Y!V36/Inputs!$C$35)*(1-Inputs!$C$36),0) -> 0
B20: Total Cash Flow | C20: =C18 -> -42000000 | D20: =D18+D19 -> 6257353.4 | E20: =E18+E19 -> 8736692.5 | F20: =F18+F19 -> 11448492 | G20: =G18+G19 -> 13316985 | H20: =H18+H19 -> 13890328 | I20: =I18+I19 -> 14486748 | J20: =J18+J19 -> 15107138 | K20: =K18+K19 -> 2.5287904e+08 | ... W20: =W18+W19 -> 0
B21: Discount Factor | C21: =1/(1+Inputs!$C$34)^0 -> 1 | D21: =1/(1+Inputs!$C$34)^1 -> 0.91324201 | E21: =1/(1+Inputs!$C$34)^2 -> 0.83401097 | F21: =1/(1+Inputs!$C$34)^3 -> 0.76165385 | G21: =1/(1+Inputs!$C$34)^4 -> 0.69557429 | H21: =1/(1+Inputs!$C$34)^5 -> 0.63522767 | I21: =1/(1+Inputs!$C$34)^6 -> 0.58011659 | J21: =1/(1+Inputs!$C$34)^7 -> 0.52978684 | K21: =1/(1+Inputs!$C$34)^8 -> 0.4838236 | L21: =1/(1+Inputs!$C$34)^9 -> 0.44184803 | M21: =1/(1+Inputs!$C$34)^10 -> 0.40351419 | N21: =1/(1+Inputs!$C$34)^11 -> 0.36850611 | O21: =1/(1+Inputs!$C$34)^12 -> 0.33653526 | P21: =1/(1+Inputs!$C$34)^13 -> 0.30733813 | Q21: =1/(1+Inputs!$C$34)^14 -> 0.2806741 | R21: =1/(1+Inputs!$C$34)^15 -> 0.25632337 | S21: =1/(1+Inputs!$C$34)^16 -> 0.23408527 | T21: =1/(1+Inputs!$C$34)^17 -> 0.21377651 | U21: =1/(1+Inputs!$C$34)^18 -> 0.19522969 | V21: =1/(1+Inputs!$C$34)^19 -> 0.17829195 | W21: =1/(1+Inputs!$C$34)^20 -> 0.1628237
B22: PV of Cash Flow | C22: =C20*C21 -> -42000000 | D22: =D20*D21 -> 5714478 | E22: =E20*E21 -> 7286497.3 | F22: =F20*F21 -> 8719788.2 | G22: =G20*G21 -> 9262952.3 | H22: =H20*H21 -> 8823520.7 | I22: =I20*I21 -> 8404003.1 | J22: =J20*J21 -> 8003563.1 | ... W22: =W20*W21 -> 0
B23: Cumulative Cash Flow | C23: =C20 -> -42000000 | D23: =C23+D20 -> -35742647 | E23: =D23+E20 -> -27005954 | F23: =E23+F20 -> -15557462 | G23: =F23+G20 -> -2240477.1 | H23: =G23+H20 -> 11649851 | I23: =H23+I20 -> 26136599 | J23: =I23+J20 -> 41243738 | K23: =J23+K20 -> 2.9412278e+08 | ... W23: =V23+W20 -> 2.9412278e+08
B24: NPV | C24: =SUM(C22:W22) -> 1.3656365e+08
B25: IRR | C25: =IRR(C20:W20) -> 0.38501004
B26: Equity Multiple (Total CF / Initial) | C26: =SUMIF(C20:W20,">0")/(-C20) -> 8.0029233
B27: 10-Year Hold
B28: Period | C28: Y0 | D28: Y1 | E28: Y2 | F28: Y3 | G28: Y4 | H28: Y5 | I28: Y6 | J28: Y7 | K28: Y8 | L28: Y9 | M28: Y10 | N28: Y11 | O28: Y12 | P28: Y13 | Q28: Y14 | R28: Y15 | S28: Y16 | T28: Y17 | U28: Y18 | V28: Y19 | W28: Y20
B29: Operating FCF | C29: =-Inputs!$C$33 -> -42000000 | D29: =IF(1<=10,CashFlow_20Y!C34,0) -> 6257353.4 | E29: =IF(2<=10,CashFlow_20Y!D34,0) -> 8736692.5 | F29: =IF(3<=10,CashFlow_20Y!E34,0) -> 11448492 | G29: =IF(4<=10,CashFlow_20Y!F34,0) -> 13316985 | H29: =IF(5<=10,CashFlow_20Y!G34,0) -> 13890328 | I29: =IF(6<=10,CashFlow_20Y!H34,0) -> 14486748 | J29: =IF(7<=10,CashFlow_20Y!I34,0) -> 15107138 | K29: =IF(8<=10,CashFlow_20Y!J34,0) -> 10214224 | L29: =IF(9<=10,CashFlow_20Y!K34,0) -> 16423568 | M29: =IF(10<=10,CashFlow_20Y!L34,0) -> 17121567 | N29: =IF(11<=10,CashFlow_20Y!M34,0) -> 0 | O29: =IF(12<=10,CashFlow_20Y!N34,0) -> 0 | P29: =IF(13<=10,CashFlow_20Y!O34,0) -> 0 | Q29: =IF(14<=10,CashFlow_20Y!P34,0) -> 0 | R29: =IF(15<=10,CashFlow_20Y!Q34,0) -> 0 | S29: =IF(16<=10,CashFlow_20Y!R34,0) -> 0 | T29: =IF(17<=10,CashFlow_20Y!S34,0) -> 0 | U29: =IF(18<=10,CashFlow_20Y!T34,0) -> 0 | V29: =IF(19<=10,CashFlow_20Y!U34,0) -> 0 | W29: =IF(20<=10,CashFlow_20Y!V34,0) -> 0
B30: Terminal Value (net of selling costs) | D30: =IF(1=10,(CashFlow_20Y!C36/Inputs!$C$35)*(1-Inputs!$C$36),0) -> 0 | E30: =IF(2=10,(CashFlow_20Y!D36/Inputs!$C$35)*(1-Inputs!$C$36),0) -> 0 | F30: =IF(3=10,(CashFlow_20Y!E36/Inputs!$C$35)*(1-Inputs!$C$36),0) -> 0 | G30: =IF(4=10,(CashFlow_20Y!F36/Inputs!$C$35)*(1-Inputs!$C$36),0) -> 0 | H30: =IF(5=10,(CashFlow_20Y!G36/Inputs!$C$35)*(1-Inputs!$C$36),0) -> 0 | I30: =IF(6=10,(CashFlow_20Y!H36/Inputs!$C$35)*(1-Inputs!$C$36),0) -> 0 | J30: =IF(7=10,(CashFlow_20Y!I36/Inputs!$C$35)*(1-Inputs!$C$36),0) -> 0 | K30: =IF(8=10,(CashFlow_20Y!J36/Inputs!$C$35)*(1-Inputs!$C$36),0) -> 0 | L30: =IF(9=10,(CashFlow_20Y!K36/Inputs!$C$35)*(1-Inputs!$C$36),0) -> 0 | M30: =IF(10=10,(CashFlow_20Y!L36/Inputs!$C$35)*(1-Inputs!$C$36),0) -> 2.6321922e+08 | N30: =IF(11=10,(CashFlow_20Y!M36/Inputs!$C$35)*(1-Inputs!$C$36),0) -> 0 | O30: =IF(12=10,(CashFlow_20Y!N36/Inputs!$C$35)*(1-Inputs!$C$36),0) -> 0 | P30: =IF(13=10,(CashFlow_20Y!O36/Inputs!$C$35)*(1-Inputs!$C$36),0) -> 0 | Q30: =IF(14=10,(CashFlow_20Y!P36/Inputs!$C$35)*(1-Inputs!$C$36),0) -> 0 | R30: =IF(15=10,(CashFlow_20Y!Q36/Inputs!$C$35)*(1-Inputs!$C$36),0) -> 0 | S30: =IF(16=10,(CashFlow_20Y!R36/Inputs!$C$35)*(1-Inputs!$C$36),0) -> 0 | T30: =IF(17=10,(CashFlow_20Y!S36/Inputs!$C$35)*(1-Inputs!$C$36),0) -> 0 | U30: =IF(18=10,(CashFlow_20Y!T36/Inputs!$C$35)*(1-Inputs!$C$36),0) -> 0 | V30: =IF(19=10,(CashFlow_20Y!U36/Inputs!$C$35)*(1-Inputs!$C$36),0) -> 0 | W30: =IF(20=10,(CashFlow_20Y!V36/Inputs!$C$35)*(1-Inputs!$C$36),0) -> 0
B31: Total Cash Flow | C31: =C29 -> -42000000 | D31: =D29+D30 -> 6257353.4 | E31: =E29+E30 -> 8736692.5 | F31: =F29+F30 -> 11448492 | G31: =G29+G30 -> 13316985 | H31: =H29+H30 -> 13890328 | I31: =I29+I30 -> 14486748 | J31: =J29+J30 -> 15107138 | K31: =K29+K30 -> 10214224 | ... W31: =W29+W30 -> 0
B32: Discount Factor | C32: =1/(1+Inputs!$C$34)^0 -> 1 | D32: =1/(1+Inputs!$C$34)^1 -> 0.91324201 | E32: =1/(1+Inputs!$C$34)^2 -> 0.83401097 | F32: =1/(1+Inputs!$C$34)^3 -> 0.76165385 | G32: =1/(1+Inputs!$C$34)^4 -> 0.69557429 | H32: =1/(1+Inputs!$C$34)^5 -> 0.63522767 | I32: =1/(1+Inputs!$C$34)^6 -> 0.58011659 | J32: =1/(1+Inputs!$C$34)^7 -> 0.52978684 | K32: =1/(1+Inputs!$C$34)^8 -> 0.4838236 | L32: =1/(1+Inputs!$C$34)^9 -> 0.44184803 | M32: =1/(1+Inputs!$C$34)^10 -> 0.40351419 | N32: =1/(1+Inputs!$C$34)^11 -> 0.36850611 | O32: =1/(1+Inputs!$C$34)^12 -> 0.33653526 | P32: =1/(1+Inputs!$C$34)^13 -> 0.30733813 | Q32: =1/(1+Inputs!$C$34)^14 -> 0.2806741 | R32: =1/(1+Inputs!$C$34)^15 -> 0.25632337 | S32: =1/(1+Inputs!$C$34)^16 -> 0.23408527 | T32: =1/(1+Inputs!$C$34)^17 -> 0.21377651 | U32: =1/(1+Inputs!$C$34)^18 -> 0.19522969 | V32: =1/(1+Inputs!$C$34)^19 -> 0.17829195 | W32: =1/(1+Inputs!$C$34)^20 -> 0.1628237
B33: PV of Cash Flow | C33: =C31*C32 -> -42000000 | D33: =D31*D32 -> 5714478 | E33: =E31*E32 -> 7286497.3 | F33: =F31*F32 -> 8719788.2 | G33: =G31*G32 -> 9262952.3 | H33: =H31*H32 -> 8823520.7 | I33: =I31*I32 -> 8404003.1 | J33: =J31*J32 -> 8003563.1 | ... W33: =W31*W32 -> 0
B34: Cumulative Cash Flow | C34: =C31 -> -42000000 | D34: =C34+D31 -> -35742647 | E34: =D34+E31 -> -27005954 | F34: =E34+F31 -> -15557462 | G34: =F34+G31 -> -2240477.1 | H34: =G34+H31 -> 11649851 | I34: =H34+I31 -> 26136599 | J34: =I34+J31 -> 41243738 | K34: =J34+K31 -> 51457962 | ... W34: =V34+W31 -> 3.4822232e+08
B35: NPV | C35: =SUM(C33:W33) -> 1.3953489e+08
B36: IRR | C36: =IRR(C31:W31) -> 0.34672466
B37: Equity Multiple (Total CF / Initial) | C37: =SUMIF(C31:W31,">0")/(-C31) -> 9.2910075
B38: 12-Year Hold
B39: Period | C39: Y0 | D39: Y1 | E39: Y2 | F39: Y3 | G39: Y4 | H39: Y5 | I39: Y6 | J39: Y7 | K39: Y8 | L39: Y9 | M39: Y10 | N39: Y11 | O39: Y12 | P39: Y13 | Q39: Y14 | R39: Y15 | S39: Y16 | T39: Y17 | U39: Y18 | V39: Y19 | W39: Y20
B40: Operating FCF | C40: =-Inputs!$C$33 -> -42000000 | D40: =IF(1<=12,CashFlow_20Y!C34,0) -> 6257353.4 | E40: =IF(2<=12,CashFlow_20Y!D34,0) -> 8736692.5 | F40: =IF(3<=12,CashFlow_20Y!E34,0) -> 11448492 | G40: =IF(4<=12,CashFlow_20Y!F34,0) -> 13316985 | H40: =IF(5<=12,CashFlow_20Y!G34,0) -> 13890328 | I40: =IF(6<=12,CashFlow_20Y!H34,0) -> 14486748 | J40: =IF(7<=12,CashFlow_20Y!I34,0) -> 15107138 | K40: =IF(8<=12,CashFlow_20Y!J34,0) -> 10214224 | L40: =IF(9<=12,CashFlow_20Y!K34,0) -> 16423568 | M40: =IF(10<=12,CashFlow_20Y!L34,0) -> 17121567 | N40: =IF(11<=12,CashFlow_20Y!M34,0) -> 17847456 | O40: =IF(12<=12,CashFlow_20Y!N34,0) -> 18602309 | P40: =IF(13<=12,CashFlow_20Y!O34,0) -> 0 | Q40: =IF(14<=12,CashFlow_20Y!P34,0) -> 0 | R40: =IF(15<=12,CashFlow_20Y!Q34,0) -> 0 | S40: =IF(16<=12,CashFlow_20Y!R34,0) -> 0 | T40: =IF(17<=12,CashFlow_20Y!S34,0) -> 0 | U40: =IF(18<=12,CashFlow_20Y!T34,0) -> 0 | V40: =IF(19<=12,CashFlow_20Y!U34,0) -> 0 | W40: =IF(20<=12,CashFlow_20Y!V34,0) -> 0
B41: Terminal Value (net of selling costs) | D41: =IF(1=12,(CashFlow_20Y!C36/Inputs!$C$35)*(1-Inputs!$C$36),0) -> 0 | E41: =IF(2=12,(CashFlow_20Y!D36/Inputs!$C$35)*(1-Inputs!$C$36),0) -> 0 | F41: =IF(3=12,(CashFlow_20Y!E36/Inputs!$C$35)*(1-Inputs!$C$36),0) -> 0 | G41: =IF(4=12,(CashFlow_20Y!F36/Inputs!$C$35)*(1-Inputs!$C$36),0) -> 0 | H41: =IF(5=12,(CashFlow_20Y!G36/Inputs!$C$35)*(1-Inputs!$C$36),0) -> 0 | I41: =IF(6=12,(CashFlow_20Y!H36/Inputs!$C$35)*(1-Inputs!$C$36),0) -> 0 | J41: =IF(7=12,(CashFlow_20Y!I36/Inputs!$C$35)*(1-Inputs!$C$36),0) -> 0 | K41: =IF(8=12,(CashFlow_20Y!J36/Inputs!$C$35)*(1-Inputs!$C$36),0) -> 0 | L41: =IF(9=12,(CashFlow_20Y!K36/Inputs!$C$35)*(1-Inputs!$C$36),0) -> 0 | M41: =IF(10=12,(CashFlow_20Y!L36/Inputs!$C$35)*(1-Inputs!$C$36),0) -> 0 | N41: =IF(11=12,(CashFlow_20Y!M36/Inputs!$C$35)*(1-Inputs!$C$36),0) -> 0 | O41: =IF(12=12,(CashFlow_20Y!N36/Inputs!$C$35)*(1-Inputs!$C$36),0) -> 2.8542379e+08 | P41: =IF(13=12,(CashFlow_20Y!O36/Inputs!$C$35)*(1-Inputs!$C$36),0) -> 0 | Q41: =IF(14=12,(CashFlow_20Y!P36/Inputs!$C$35)*(1-Inputs!$C$36),0) -> 0 | R41: =IF(15=12,(CashFlow_20Y!Q36/Inputs!$C$35)*(1-Inputs!$C$36),0) -> 0 | S41: =IF(16=12,(CashFlow_20Y!R36/Inputs!$C$35)*(1-Inputs!$C$36),0) -> 0 | T41: =IF(17=12,(CashFlow_20Y!S36/Inputs!$C$35)*(1-Inputs!$C$36),0) -> 0 | U41: =IF(18=12,(CashFlow_20Y!T36/Inputs!$C$35)*(1-Inputs!$C$36),0) -> 0 | V41: =IF(19=12,(CashFlow_20Y!U36/Inputs!$C$35)*(1-Inputs!$C$36),0) -> 0 | W41: =IF(20=12,(CashFlow_20Y!V36/Inputs!$C$35)*(1-Inputs!$C$36),0) -> 0
B42: Total Cash Flow | C42: =C40 -> -42000000 | D42: =D40+D41 -> 6257353.4 | E42: =E40+E41 -> 8736692.5 | F42: =F40+F41 -> 11448492 | G42: =G40+G41 -> 13316985 | H42: =H40+H41 -> 13890328 | I42: =I40+I41 -> 14486748 | J42: =J40+J41 -> 15107138 | K42: =K40+K41 -> 10214224 | ... W42: =W40+W41 -> 0
...

Sheet Sensitivity
B2: SENSITIVITY ANALYSIS
B3: 10-Year Hold: NPV & IRR vs. Discount Rate × Exit Cap Rate
B6: Reference Cash Flow (10-Year, fixed)
B7: Year | C7: Y0 | D7: Y1 | E7: Y2 | F7: Y3 | G7: Y4 | H7: Y5 | I7: Y6 | J7: Y7 | K7: Y8 | L7: Y9 | M7: Y10
B8: Operating FCF | C8: =-Inputs!$C$33 -> -42000000 | D8: =CashFlow_20Y!C34 -> 6257353.4 | E8: =CashFlow_20Y!D34 -> 8736692.5 | F8: =CashFlow_20Y!E34 -> 11448492 | G8: =CashFlow_20Y!F34 -> 13316985 | H8: =CashFlow_20Y!G34 -> 13890328 | I8: =CashFlow_20Y!H34 -> 14486748 | J8: =CashFlow_20Y!I34 -> 15107138 | K8: =CashFlow_20Y!J34 -> 10214224 | ... M8: =CashFlow_20Y!L34 -> 17121567
B9: Forward NOI (Y+1) | D9: =CashFlow_20Y!C36 -> 9928059.6 | E9: =CashFlow_20Y!D36 -> 13009650 | F9: =CashFlow_20Y!E36 -> 15132937 | G9: =CashFlow_20Y!F36 -> 15768244 | H9: =CashFlow_20Y!G36 -> 16428749 | I9: =CashFlow_20Y!H36 -> 17115417 | J9: =CashFlow_20Y!I36 -> 17829250 | K9: =CashFlow_20Y!J36 -> 18571287 | ... M9: =CashFlow_20Y!L36 -> 20144328
B12: TABLE 1 — NPV ($) | Rows: Discount Rate | Cols: Exit Cap Rate (10-Year Hold)
B13: Discount Rate ↓ / Exit Cap → | C13: 0.055 | D13: 0.065 | E13: 0.075 | F13: 0.085 | G13: 0.095
B14: 0.07 | C14: =SUMPRODUCT($C$8:$M$8/((1+$B14)^(COLUMN($C$8:$M$8)-COLUMN($C$8))))+($M$9/C$13*(1-Inputs!$C$36))/((1+$B14)^10) -> 2.2599486e+08 | D14: =SUMPRODUCT($C$8:$M$8/((1+$B14)^(COLUMN($C$8:$M$8)-COLUMN($C$8))))+($M$9/D$13*(1-Inputs!$C$36))/((1+$B14)^10) -> 1.979234e+08 | E14: =SUMPRODUCT($C$8:$M$8/((1+$B14)^(COLUMN($C$8:$M$8)-COLUMN($C$8))))+($M$9/E$13*(1-Inputs!$C$36))/((1+$B14)^10) -> 1.7733766e+08 | F14: =SUMPRODUCT($C$8:$M$8/((1+$B14)^(COLUMN($C$8:$M$8)-COLUMN($C$8))))+($M$9/F$13*(1-Inputs!$C$36))/((1+$B14)^10) -> 1.6159562e+08 | G14: =SUMPRODUCT($C$8:$M$8/((1+$B14)^(COLUMN($C$8:$M$8)-COLUMN($C$8))))+($M$9/G$13*(1-Inputs!$C$36))/((1+$B14)^10) -> 1.491677e+08
B15: 0.08 | C15: =SUMPRODUCT($C$8:$M$8/((1+$B15)^(COLUMN($C$8:$M$8)-COLUMN($C$8))))+($M$9/C$13*(1-Inputs!$C$36))/((1+$B15)^10) -> 2.0547961e+08 | D15: =SUMPRODUCT($C$8:$M$8/((1+$B15)^(COLUMN($C$8:$M$8)-COLUMN($C$8))))+($M$9/D$13*(1-Inputs!$C$36))/((1+$B15)^10) -> 1.7990169e+08 | E15: =SUMPRODUCT($C$8:$M$8/((1+$B15)^(COLUMN($C$8:$M$8)-COLUMN($C$8))))+($M$9/E$13*(1-Inputs!$C$36))/((1+$B15)^10) -> 1.6114454e+08 | F15: =SUMPRODUCT($C$8:$M$8/((1+$B15)^(COLUMN($C$8:$M$8)-COLUMN($C$8))))+($M$9/F$13*(1-Inputs!$C$36))/((1+$B15)^10) -> 1.4680085e+08 | G15: =SUMPRODUCT($C$8:$M$8/((1+$B15)^(COLUMN($C$8:$M$8)-COLUMN($C$8))))+($M$9/G$13*(1-Inputs!$C$36))/((1+$B15)^10) -> 1.3547688e+08
B16: 0.09 | C16: =SUMPRODUCT($C$8:$M$8/((1+$B16)^(COLUMN($C$8:$M$8)-COLUMN($C$8))))+($M$9/C$13*(1-Inputs!$C$36))/((1+$B16)^10) -> 1.86837e+08 | D16: =SUMPRODUCT($C$8:$M$8/((1+$B16)^(COLUMN($C$8:$M$8)-COLUMN($C$8))))+($M$9/D$13*(1-Inputs!$C$36))/((1+$B16)^10) -> 1.6351113e+08 | E16: =SUMPRODUCT($C$8:$M$8/((1+$B16)^(COLUMN($C$8:$M$8)-COLUMN($C$8))))+($M$9/E$13*(1-Inputs!$C$36))/((1+$B16)^10) -> 1.4640549e+08 | F16: =SUMPRODUCT($C$8:$M$8/((1+$B16)^(COLUMN($C$8:$M$8)-COLUMN($C$8))))+($M$9/F$13*(1-Inputs!$C$36))/((1+$B16)^10) -> 1.3332471e+08 | G16: =SUMPRODUCT($C$8:$M$8/((1+$B16)^(COLUMN($C$8:$M$8)-COLUMN($C$8))))+($M$9/G$13*(1-Inputs!$C$36))/((1+$B16)^10) -> 1.2299778e+08
B17: 0.095 | C17: =SUMPRODUCT($C$8:$M$8/((1+$B17)^(COLUMN($C$8:$M$8)-COLUMN($C$8))))+($M$9/C$13*(1-Inputs!$C$36))/((1+$B17)^10) -> 1.7815769e+08 | D17: =SUMPRODUCT($C$8:$M$8/((1+$B17)^(COLUMN($C$8:$M$8)-COLUMN($C$8))))+($M$9/D$13*(1-Inputs!$C$36))/((1+$B17)^10) -> 1.558753e+08 | E17: =SUMPRODUCT($C$8:$M$8/((1+$B17)^(COLUMN($C$8:$M$8)-COLUMN($C$8))))+($M$9/E$13*(1-Inputs!$C$36))/((1+$B17)^10) -> 1.3953489e+08 | F17: =SUMPRODUCT($C$8:$M$8/((1+$B17)^(COLUMN($C$8:$M$8)-COLUMN($C$8))))+($M$9/F$13*(1-Inputs!$C$36))/((1+$B17)^10) -> 1.2703928e+08 | G17: =SUMPRODUCT($C$8:$M$8/((1+$B17)^(COLUMN($C$8:$M$8)-COLUMN($C$8))))+($M$9/G$13*(1-Inputs!$C$36))/((1+$B17)^10) -> 1.1717432e+08
B18: 0.1 | C18: =SUMPRODUCT($C$8:$M$8/((1+$B18)^(COLUMN($C$8:$M$8)-COLUMN($C$8))))+($M$9/C$13*(1-Inputs!$C$36))/((1+$B18)^10) -> 1.6987696e+08 | D18: =SUMPRODUCT($C$8:$M$8/((1+$B18)^(COLUMN($C$8:$M$8)-COLUMN($C$8))))+($M$9/D$13*(1-Inputs!$C$36))/((1+$B18)^10) -> 1.4858695e+08 | E18: =SUMPRODUCT($C$8:$M$8/((1+$B18)^(COLUMN($C$8:$M$8)-COLUMN($C$8))))+($M$9/E$13*(1-Inputs!$C$36))/((1+$B18)^10) -> 1.3297427e+08 | F18: =SUMPRODUCT($C$8:$M$8/((1+$B18)^(COLUMN($C$8:$M$8)-COLUMN($C$8))))+($M$9/F$13*(1-Inputs!$C$36))/((1+$B18)^10) -> 1.2103516e+08 | G18: =SUMPRODUCT($C$8:$M$8/((1+$B18)^(COLUMN($C$8:$M$8)-COLUMN($C$8))))+($M$9/G$13*(1-Inputs!$C$36))/((1+$B18)^10) -> 1.1160955e+08
B19: 0.11 | C19: =SUMPRODUCT($C$8:$M$8/((1+$B19)^(COLUMN($C$8:$M$8)-COLUMN($C$8))))+($M$9/C$13*(1-Inputs!$C$36))/((1+$B19)^10) -> 1.5443041e+08 | D19: =SUMPRODUCT($C$8:$M$8/((1+$B19)^(COLUMN($C$8:$M$8)-COLUMN($C$8))))+($M$9/D$13*(1-Inputs!$C$36))/((1+$B19)^10) -> 1.349825e+08 | E19: =SUMPRODUCT($C$8:$M$8/((1+$B19)^(COLUMN($C$8:$M$8)-COLUMN($C$8))))+($M$9/E$13*(1-Inputs!$C$36))/((1+$B19)^10) -> 1.207207e+08 | F19: =SUMPRODUCT($C$8:$M$8/((1+$B19)^(COLUMN($C$8:$M$8)-COLUMN($C$8))))+($M$9/F$13*(1-Inputs!$C$36))/((1+$B19)^10) -> 1.0981461e+08 | G19: =SUMPRODUCT($C$8:$M$8/((1+$B19)^(COLUMN($C$8:$M$8)-COLUMN($C$8))))+($M$9/G$13*(1-Inputs!$C$36))/((1+$B19)^10) -> 1.0120454e+08
B20: 0.12 | C20: =SUMPRODUCT($C$8:$M$8/((1+$B20)^(COLUMN($C$8:$M$8)-COLUMN($C$8))))+($M$9/C$13*(1-Inputs!$C$36))/((1+$B20)^10) -> 1.4034674e+08 | D20: =SUMPRODUCT($C$8:$M$8/((1+$B20)^(COLUMN($C$8:$M$8)-COLUMN($C$8))))+($M$9/D$13*(1-Inputs!$C$36))/((1+$B20)^10) -> 1.2256712e+08 | E20: =SUMPRODUCT($C$8:$M$8/((1+$B20)^(COLUMN($C$8:$M$8)-COLUMN($C$8))))+($M$9/E$13*(1-Inputs!$C$36))/((1+$B20)^10) -> 1.0952873e+08 | F20: =SUMPRODUCT($C$8:$M$8/((1+$B20)^(COLUMN($C$8:$M$8)-COLUMN($C$8))))+($M$9/F$13*(1-Inputs!$C$36))/((1+$B20)^10) -> 99558193 | G20: =SUMPRODUCT($C$8:$M$8/((1+$B20)^(COLUMN($C$8:$M$8)-COLUMN($C$8))))+($M$9/G$13*(1-Inputs!$C$36))/((1+$B20)^10) -> 91686719
B23: TABLE 2 — NPV ($) | Rows: Discount Rate | Cols: Holding Period (years)
B24: Discount Rate ↓ / Hold (yrs) → | C24: 5 | D24: 8 | E24: 10 | F24: 12 | G24: 20
B25: 0.07 | C25: =-Inputs!$C$33+SUMPRODUCT(CashFlow_20Y!$C$34:$V$34*(COLUMN(CashFlow_20Y!$C$34:$V$34)-COLUMN(CashFlow_20Y!$C$34)+1<=C$24)*(1/(1+$B25)^(COLUMN(CashFlow_20Y!$C$34:$V$34)-COLUMN(CashFlow_20Y!$C$34)+1)))+((INDEX(CashFlow_20Y!$C$36:$V$36,1,C$24)/Inputs!$C$35)*(1-Inputs!$C$36))/((1+$B25)^C$24) -> 1.5394343e+08 | D25: =-Inputs!$C$33+SUMPRODUCT(CashFlow_20Y!$C$34:$V$34*(COLUMN(CashFlow_20Y!$C$34:$V$34)-COLUMN(CashFlow_20Y!$C$34)+1<=D$24)*(1/(1+$B25)^(COLUMN(CashFlow_20Y!$C$34:$V$34)-COLUMN(CashFlow_20Y!$C$34)+1)))+((INDEX(CashFlow_20Y!$C$36:$V$36,1,D$24)/Inputs!$C$35)*(1-Inputs!$C$36))/((1+$B25)^D$24) -> 1.6712642e+08 | E25: =-Inputs!$C$33+SUMPRODUCT(CashFlow_20Y!$C$34:$V$34*(COLUMN(CashFlow_20Y!$C$34:$V$34)-COLUMN(CashFlow_20Y!$C$34)+1<=E$24)*(1/(1+$B25)^(COLUMN(CashFlow_20Y!$C$34:$V$34)-COLUMN(CashFlow_20Y!$C$34)+1)))+((INDEX(CashFlow_20Y!$C$36:$V$36,1,E$24)/Inputs!$C$35)*(1-Inputs!$C$36))/((1+$B25)^E$24) -> 1.7733766e+08 | F25: =-Inputs!$C$33+SUMPRODUCT(CashFlow_20Y!$C$34:$V$34*(COLUMN(CashFlow_20Y!$C$34:$V$34)-COLUMN(CashFlow_20Y!$C$34)+1<=F$24)*(1/(1+$B25)^(COLUMN(CashFlow_20Y!$C$34:$V$34)-COLUMN(CashFlow_20Y!$C$34)+1)))+((INDEX(CashFlow_20Y!$C$36:$V$36,1,F$24)/Inputs!$C$35)*(1-Inputs!$C$36))/((1+$B25)^F$24) -> 1.8700078e+08 | G25: =-Inputs!$C$33+SUMPRODUCT(CashFlow_20Y!$C$34:$V$34*(COLUMN(CashFlow_20Y!$C$34:$V$34)-COLUMN(CashFlow_20Y!$C$34)+1<=G$24)*(1/(1+$B25)^(COLUMN(CashFlow_20Y!$C$34:$V$34)-COLUMN(CashFlow_20Y!$C$34)+1)))+((INDEX(CashFlow_20Y!$C$36:$V$36,1,G$24)/Inputs!$C$35)*(1-Inputs!$C$36))/((1+$B25)^G$24) -> 2.176849e+08
B26: 0.08 | C26: =-Inputs!$C$33+SUMPRODUCT(CashFlow_20Y!$C$34:$V$34*(COLUMN(CashFlow_20Y!$C$34:$V$34)-COLUMN(CashFlow_20Y!$C$34)+1<=C$24)*(1/(1+$B26)^(COLUMN(CashFlow_20Y!$C$34:$V$34)-COLUMN(CashFlow_20Y!$C$34)+1)))+((INDEX(CashFlow_20Y!$C$36:$V$36,1,C$24)/Inputs!$C$35)*(1-Inputs!$C$36))/((1+$B26)^C$24) -> 1.4571434e+08 | D26: =-Inputs!$C$33+SUMPRODUCT(CashFlow_20Y!$C$34:$V$34*(COLUMN(CashFlow_20Y!$C$34:$V$34)-COLUMN(CashFlow_20Y!$C$34)+1<=D$24)*(1/(1+$B26)^(COLUMN(CashFlow_20Y!$C$34:$V$34)-COLUMN(CashFlow_20Y!$C$34)+1)))+((INDEX(CashFlow_20Y!$C$36:$V$36,1,D$24)/Inputs!$C$35)*(1-Inputs!$C$36))/((1+$B26)^D$24) -> 1.541809e+08 | E26: =-Inputs!$C$33+SUMPRODUCT(CashFlow_20Y!$C$34:$V$34*(COLUMN(CashFlow_20Y!$C$34:$V$34)-COLUMN(CashFlow_20Y!$C$34)+1<=E$24)*(1/(1+$B26)^(COLUMN(CashFlow_20Y!$C$34:$V$34)-COLUMN(CashFlow_20Y!$C$34)+1)))+((INDEX(CashFlow_20Y!$C$36:$V$36,1,E$24)/Inputs!$C$35)*(1-Inputs!$C$36))/((1+$B26)^E$24) -> 1.6114454e+08 | F26: =-Inputs!$C$33+SUMPRODUCT(CashFlow_20Y!$C$34:$V$34*(COLUMN(CashFlow_20Y!$C$34:$V$34)-COLUMN(CashFlow_20Y!$C$34)+1<=F$24)*(1/(1+$B26)^(COLUMN(CashFlow_20Y!$C$34:$V$34)-COLUMN(CashFlow_20Y!$C$34)+1)))+((INDEX(CashFlow_20Y!$C$36:$V$36,1,F$24)/Inputs!$C$35)*(1-Inputs!$C$36))/((1+$B26)^F$24) -> 1.6761053e+08 | G26: =-Inputs!$C$33+SUMPRODUCT(CashFlow_20Y!$C$34:$V$34*(COLUMN(CashFlow_20Y!$C$34:$V$34)-COLUMN(CashFlow_20Y!$C$34)+1<=G$24)*(1/(1+$B26)^(COLUMN(CashFlow_20Y!$C$34:$V$34)-COLUMN(CashFlow_20Y!$C$34)+1)))+((INDEX(CashFlow_20Y!$C$36:$V$36,1,G$24)/Inputs!$C$35)*(1-Inputs!$C$36))/((1+$B26)^G$24) -> 1.8657066e+08
B27: 0.09 | C27: =-Inputs!$C$33+SUMPRODUCT(CashFlow_20Y!$C$34:$V$34*(COLUMN(CashFlow_20Y!$C$34:$V$34)-COLUMN(CashFlow_20Y!$C$34)+1<=C$24)*(1/(1+$B27)^(COLUMN(CashFlow_20Y!$C$34:$V$34)-COLUMN(CashFlow_20Y!$C$34)+1)))+((INDEX(CashFlow_20Y!$C$36:$V$36,1,C$24)/Inputs!$C$35)*(1-Inputs!$C$36))/((1+$B27)^C$24) -> 1.3791648e+08 | D27: =-Inputs!$C$33+SUMPRODUCT(CashFlow_20Y!$C$34:$V$34*(COLUMN(CashFlow_20Y!$C$34:$V$34)-COLUMN(CashFlow_20Y!$C$34)+1<=D$24)*(1/(1+$B27)^(COLUMN(CashFlow_20Y!$C$34:$V$34)-COLUMN(CashFlow_20Y!$C$34)+1)))+((INDEX(CashFlow_20Y!$C$36:$V$36,1,D$24)/Inputs!$C$35)*(1-Inputs!$C$36))/((1+$B27)^D$24) -> 1.4220994e+08 | E27: =-Inputs!$C$33+SUMPRODUCT(CashFlow_20Y!$C$34:$V$34*(COLUMN(CashFlow_20Y!$C$34:$V$34)-COLUMN(CashFlow_20Y!$C$34)+1<=E$24)*(1/(1+$B27)^(COLUMN(CashFlow_20Y!$C$34:$V$34)-COLUMN(CashFlow_20Y!$C$34)+1)))+((INDEX(CashFlow_20Y!$C$36:$V$36,1,E$24)/Inputs!$C$35)*(1-Inputs!$C$36))/((1+$B27)^E$24) -> 1.4640549e+08 | F27: =-Inputs!$C$33+SUMPRODUCT(CashFlow_20Y!$C$34:$V$34*(COLUMN(CashFlow_20Y!$C$34:$V$34)-COLUMN(CashFlow_20Y!$C$34)+1<=F$24)*(1/(1+$B27)^(COLUMN(CashFlow_20Y!$C$34:$V$34)-COLUMN(CashFlow_20Y!$C$34)+1)))+((INDEX(CashFlow_20Y!$C$36:$V$36,1,F$24)/Inputs!$C$35)*(1-Inputs!$C$36))/((1+$B27)^F$24) -> 1.5022716e+08 | G27: =-Inputs!$C$33+SUMPRODUCT(CashFlow_20Y!$C$34:$V$34*(COLUMN(CashFlow_20Y!$C$34:$V$34)-COLUMN(CashFlow_20Y!$C$34)+1<=G$24)*(1/(1+$B27)^(COLUMN(CashFlow_20Y!$C$34:$V$34)-COLUMN(CashFlow_20Y!$C$34)+1)))+((INDEX(CashFlow_20Y!$C$36:$V$36,1,G$24)/Inputs!$C$35)*(1-Inputs!$C$36))/((1+$B27)^G$24) -> 1.6017739e+08
B28: 0.095 | C28: =-Inputs!$C$33+SUMPRODUCT(CashFlow_20Y!$C$34:$V$34*(COLUMN(CashFlow_20Y!$C$34:$V$34)-COLUMN(CashFlow_20Y!$C$34)+1<=C$24)*(1/(1+$B28)^(COLUMN(CashFlow_20Y!$C$34:$V$34)-COLUMN(CashFlow_20Y!$C$34)+1)))+((INDEX(CashFlow_20Y!$C$36:$V$36,1,C$24)/Inputs!$C$35)*(1-Inputs!$C$36))/((1+$B28)^C$24) -> 1.3417091e+08 | D28: =-Inputs!$C$33+SUMPRODUCT(CashFlow_20Y!$C$34:$V$34*(COLUMN(CashFlow_20Y!$C$34:$V$34)-COLUMN(CashFlow_20Y!$C$34)+1<=D$24)*(1/(1+$B28)^(COLUMN(CashFlow_20Y!$C$34:$V$34)-COLUMN(CashFlow_20Y!$C$34)+1)))+((INDEX(CashFlow_20Y!$C$36:$V$36,1,D$24)/Inputs!$C$35)*(1-Inputs!$C$36))/((1+$B28)^D$24) -> 1.3656365e+08 | E28: =-Inputs!$C$33+SUMPRODUCT(CashFlow_20Y!$C$34:$V$34*(COLUMN(CashFlow_20Y!$C$34:$V$34)-COLUMN(CashFlow_20Y!$C$34)+1<=E$24)*(1/(1+$B28)^(COLUMN(CashFlow_20Y!$C$34:$V$34)-COLUMN(CashFlow_20Y!$C$34)+1)))+((INDEX(CashFlow_20Y!$C$36:$V$36,1,E$24)/Inputs!$C$35)*(1-Inputs!$C$36))/((1+$B28)^E$24) -> 1.3953489e+08 | F28: =-Inputs!$C$33+SUMPRODUCT(CashFlow_20Y!$C$34:$V$34*(COLUMN(CashFlow_20Y!$C$34:$V$34)-COLUMN(CashFlow_20Y!$C$34)+1<=F$24)*(1/(1+$B28)^(COLUMN(CashFlow_20Y!$C$34:$V$34)-COLUMN(CashFlow_20Y!$C$34)+1)))+((INDEX(CashFlow_20Y!$C$36:$V$36,1,F$24)/Inputs!$C$35)*(1-Inputs!$C$36))/((1+$B28)^F$24) -> 1.422146e+08 | G28: =-Inputs!$C$33+SUMPRODUCT(CashFlow_20Y!$C$34:$V$34*(COLUMN(CashFlow_20Y!$C$34:$V$34)-COLUMN(CashFlow_20Y!$C$34)+1<=G$24)*(1/(1+$B28)^(COLUMN(CashFlow_20Y!$C$34:$V$34)-COLUMN(CashFlow_20Y!$C$34)+1)))+((INDEX(CashFlow_20Y!$C$36:$V$36,1,G$24)/Inputs!$C$35)*(1-Inputs!$C$36))/((1+$B28)^G$24) -> 1.4849626e+08
B29: 0.1 | C29: =-Inputs!$C$33+SUMPRODUCT(CashFlow_20Y!$C$34:$V$34*(COLUMN(CashFlow_20Y!$C$34:$V$34)-COLUMN(CashFlow_20Y!$C$34)+1<=C$24)*(1/(1+$B29)^(COLUMN(CashFlow_20Y!$C$34:$V$34)-COLUMN(CashFlow_20Y!$C$34)+1)))+((INDEX(CashFlow_20Y!$C$36:$V$36,1,C$24)/Inputs!$C$35)*(1-Inputs!$C$36))/((1+$B29)^C$24) -> 1.3052336e+08 | D29: =-Inputs!$C$33+SUMPRODUCT(CashFlow_20Y!$C$34:$V$34*(COLUMN(CashFlow_20Y!$C$34:$V$34)-COLUMN(CashFlow_20Y!$C$34)+1<=D$24)*(1/(1+$B29)^(COLUMN(CashFlow_20Y!$C$34:$V$34)-COLUMN(CashFlow_20Y!$C$34)+1)))+((INDEX(CashFlow_20Y!$C$36:$V$36,1,D$24)/Inputs!$C$35)*(1-Inputs!$C$36))/((1+$B29)^D$24) -> 1.3113049e+08 | E29: =-Inputs!$C$33+SUMPRODUCT(CashFlow_20Y!$C$34:$V$34*(COLUMN(CashFlow_20Y!$C$34:$V$34)-COLUMN(CashFlow_20Y!$C$34)+1<=E$24)*(1/(1+$B29)^(COLUMN(CashFlow_20Y!$C$34:$V$34)-COLUMN(CashFlow_20Y!$C$34)+1)))+((INDEX(CashFlow_20Y!$C$36:$V$36,1,E$24)/Inputs!$C$35)*(1-Inputs!$C$36))/((1+$B29)^E$24) -> 1.3297427e+08 | F29: =-Inputs!$C$33+SUMPRODUCT(CashFlow_20Y!$C$34:$V$34*(COLUMN(CashFlow_20Y!$C$34:$V$34)-COLUMN(CashFlow_20Y!$C$34)+1<=F$24)*(1/(1+$B29)^(COLUMN(CashFlow_20Y!$C$34:$V$34)-COLUMN(CashFlow_20Y!$C$34)+1)))+((INDEX(CashFlow_20Y!$C$36:$V$36,1,F$24)/Inputs!$C$35)*(1-Inputs!$C$36))/((1+$B29)^F$24) -> 1.3461938e+08 | G29: =-Inputs!$C$33+SUMPRODUCT(CashFlow_20Y!$C$34:$V$34*(COLUMN(CashFlow_20Y!$C$34:$V$34)-COLUMN(CashFlow_20Y!$C$34)+1<=G$24)*(1/(1+$B29)^(COLUMN(CashFlow_20Y!$C$34:$V$34)-COLUMN(CashFlow_20Y!$C$34)+1)))+((INDEX(CashFlow_20Y!$C$36:$V$36,1,G$24)/Inputs!$C$35)*(1-Inputs!$C$36))/((1+$B29)^G$24) -> 1.3770862e+08
B30: 0.11 | C30: =-Inputs!$C$33+SUMPRODUCT(CashFlow_20Y!$C$34:$V$34*(COLUMN(CashFlow_20Y!$C$34:$V$34)-COLUMN(CashFlow_20Y!$C$34)+1<=C$24)*(1/(1+$B30)^(COLUMN(CashFlow_20Y!$C$34:$V$34)-COLUMN(CashFlow_20Y!$C$34)+1)))+((INDEX(CashFlow_20Y!$C$36:$V$36,1,C$24)/Inputs!$C$35)*(1-Inputs!$C$36))/((1+$B30)^C$24) -> 1.2351033e+08 | D30: =-Inputs!$C$33+SUMPRODUCT(CashFlow_20Y!$C$34:$V$34*(COLUMN(CashFlow_20Y!$C$34:$V$34)-COLUMN(CashFlow_20Y!$C$34)+1<=D$24)*(1/(1+$B30)^(COLUMN(CashFlow_20Y!$C$34:$V$34)-COLUMN(CashFlow_20Y!$C$34)+1)))+((INDEX(CashFlow_20Y!$C$36:$V$36,1,D$24)/Inputs!$C$35)*(1-Inputs!$C$36))/((1+$B30)^D$24) -> 1.2086734e+08 | E30: =-Inputs!$C$33+SUMPRODUCT(CashFlow_20Y!$C$34:$V$34*(COLUMN(CashFlow_20Y!$C$34:$V$34)-COLUMN(CashFlow_20Y!$C$34)+1<=E$24)*(1/(1+$B30)^(COLUMN(CashFlow_20Y!$C$34:$V$34)-COLUMN(CashFlow_20Y!$C$34)+1)))+((INDEX(CashFlow_20Y!$C$36:$V$36,1,E$24)/Inputs!$C$35)*(1-Inputs!$C$36))/((1+$B30)^E$24) -> 1.207207e+08 | F30: =-Inputs!$C$33+SUMPRODUCT(CashFlow_20Y!$C$34:$V$34*(COLUMN(CashFlow_20Y!$C$34:$V$34)-COLUMN(CashFlow_20Y!$C$34)+1<=F$24)*(1/(1+$B30)^(COLUMN(CashFlow_20Y!$C$34:$V$34)-COLUMN(CashFlow_20Y!$C$34)+1)))+((INDEX(CashFlow_20Y!$C$36:$V$36,1,F$24)/Inputs!$C$35)*(1-Inputs!$C$36))/((1+$B30)^F$24) -> 1.2058475e+08 | G30: =-Inputs!$C$33+SUMPRODUCT(CashFlow_20Y!$C$34:$V$34*(COLUMN(CashFlow_20Y!$C$34:$V$34)-COLUMN(CashFlow_20Y!$C$34)+1<=G$24)*(1/(1+$B30)^(COLUMN(CashFlow_20Y!$C$34:$V$34)-COLUMN(CashFlow_20Y!$C$34)+1)))+((INDEX(CashFlow_20Y!$C$36:$V$36,1,G$24)/Inputs!$C$35)*(1-Inputs!$C$36))/((1+$B30)^G$24) -> 1.1851158e+08
B31: 0.12 | C31: =-Inputs!$C$33+SUMPRODUCT(CashFlow_20Y!$C$34:$V$34*(COLUMN(CashFlow_20Y!$C$34:$V$34)-COLUMN(CashFlow_20Y!$C$34)+1<=C$24)*(1/(1+$B31)^(COLUMN(CashFlow_20Y!$C$34:$V$34)-COLUMN(CashFlow_20Y!$C$34)+1)))+((INDEX(CashFlow_20Y!$C$36:$V$36,1,C$24)/Inputs!$C$35)*(1-Inputs!$C$36))/((1+$B31)^C$24) -> 1.1685445e+08 | D31: =-Inputs!$C$33+SUMPRODUCT(CashFlow_20Y!$C$34:$V$34*(COLUMN(CashFlow_20Y!$C$34:$V$34)-COLUMN(CashFlow_20Y!$C$34)+1<=D$24)*(1/(1+$B31)^(COLUMN(CashFlow_20Y!$C$34:$V$34)-COLUMN(CashFlow_20Y!$C$34)+1)))+((INDEX(CashFlow_20Y!$C$36:$V$36,1,D$24)/Inputs!$C$35)*(1-Inputs!$C$36))/((1+$B31)^D$24) -> 1.1135224e+08 | E31: =-Inputs!$C$33+SUMPRODUCT(CashFlow_20Y!$C$34:$V$34*(COLUMN(CashFlow_20Y!$C$34:$V$34)-COLUMN(CashFlow_20Y!$C$34)+1<=E$24)*(1/(1+$B31)^(COLUMN(CashFlow_20Y!$C$34:$V$34)-COLUMN(CashFlow_20Y!$C$34)+1)))+((INDEX(CashFlow_20Y!$C$36:$V$36,1,E$24)/Inputs!$C$35)*(1-Inputs!$C$36))/((1+$B31)^E$24) -> 1.0952873e+08 | F31: =-Inputs!$C$33+SUMPRODUCT(CashFlow_20Y!$C$34:$V$34*(COLUMN(CashFlow_20Y!$C$34:$V$34)-COLUMN(CashFlow_20Y!$C$34)+1<=F$24)*(1/(1+$B31)^(COLUMN(CashFlow_20Y!$C$34:$V$34)-COLUMN(CashFlow_20Y!$C$34)+1)))+((INDEX(CashFlow_20Y!$C$36:$V$36,1,F$24)/Inputs!$C$35)*(1-Inputs!$C$36))/((1+$B31)^F$24) -> 1.0794583e+08 | G31: =-Inputs!$C$33+SUMPRODUCT(CashFlow_20Y!$C$34:$V$34*(COLUMN(CashFlow_20Y!$C$34:$V$34)-COLUMN(CashFlow_20Y!$C$34)+1<=G$24)*(1/(1+$B31)^(COLUMN(CashFlow_20Y!$C$34:$V$34)-COLUMN(CashFlow_20Y!$C$34)+1)))+((INDEX(CashFlow_20Y!$C$36:$V$36,1,G$24)/Inputs!$C$35)*(1-Inputs!$C$36))/((1+$B31)^G$24) -> 1.0204993e+08

Sheet Summary
B2: SUMMARY DASHBOARD
B3: Side-by-side comparison of 5 holding period scenarios
B5: KEY METRICS BY HOLDING PERIOD
B6: Metric | C6: 5-Year | D6: 8-Year | E6: 10-Year | F6: 12-Year | G6: 20-Year
B7: Holding Period (years) | C7: =Inputs!C43 -> 5 | D7: =Inputs!D43 -> 8 | E7: =Inputs!E43 -> 10 | F7: =Inputs!F43 -> 12 | G7: =Inputs!G43 -> 20
B8: Initial Investment | C8: =Scenarios!C7 -> -42000000 | D8: =Scenarios!C18 -> -42000000 | E8: =Scenarios!C29 -> -42000000 | F8: =Scenarios!C40 -> -42000000 | G8: =Scenarios!C51 -> -42000000
B9: Net Present Value (NPV) | C9: =Scenarios!C13 -> 1.3417091e+08 | D9: =Scenarios!C24 -> 1.3656365e+08 | E9: =Scenarios!C35 -> 1.3953489e+08 | F9: =Scenarios!C46 -> 1.422146e+08 | G9: =Scenarios!C57 -> 1.4849626e+08
B10: Internal Rate of Return (IRR) | C10: =Scenarios!C14 -> 0.51843884 | D10: =Scenarios!C25 -> 0.38501004 | E10: =Scenarios!C36 -> 0.34672466 | F10: =Scenarios!C47 -> 0.32359078 | G10: =Scenarios!C58 -> 0.2870861
B11: Equity Multiple | C11: =Scenarios!C15 -> 6.3885436 | D11: =Scenarios!C26 -> 8.0029233 | E11: =Scenarios!C37 -> 9.2910075 | F11: =Scenarios!C48 -> 10.687539 | G11: =Scenarios!C59 -> 17.318415
B12: Profitability Index (NPV / Investment) | C12: =C9/C8 -> -3.1945455 | D12: =D9/D8 -> -3.2515155 | E12: =E9/E8 -> -3.3222593 | F12: =F9/F8 -> -3.3860619 | G12: =G9/G8 -> -3.5356253
B13: IRR Spread vs. Discount Rate | C13: =C10-Inputs!$C$34 -> 0.42343884 | D13: =D10-Inputs!$C$34 -> 0.29001004 | E13: =E10-Inputs!$C$34 -> 0.25172466 | F13: =F10-Inputs!$C$34 -> 0.22859078 | G13: =G10-Inputs!$C$34 -> 0.1920861
B16: RECOMMENDATION SUMMARY
B17: Best NPV (highest): | C17: =INDEX($C$7:$G$7,1,MATCH(MAX($C$9:$G$9),$C$9:$G$9,0)) -> 20 | D17: → NPV = | E17: =MAX($C$9:$G$9) -> 1.4849626e+08
B18: Best IRR (highest): | C18: =INDEX($C$7:$G$7,1,MATCH(MAX($C$10:$G$10),$C$10:$G$10,0)) -> 5 | D18: → IRR = | E18: =MAX($C$10:$G$10) -> 0.51843884
B21: READING THE MODEL
B22: • Shorter holds (5–8 yrs) emphasize exit-value timing; sensitive to terminal cap rate.
B23: • Longer holds (12–20 yrs) capture more compound NOI growth but absorb more renovation cycles.
B24: • Development-stage assets benefit from longer holds because Year 1–3 ramp dilutes early IRR.
B25: • Toggle Inputs!C37 (renovation cycle 7–10 yrs) to test capex timing impact on hold-period choice.

Sheet Charts
B2: VISUAL ANALYTICS
B3: All charts update automatically when Inputs change.
B5: Data Block 1: NPV & IRR by Holding Period
B6: Holding Period | C6: NPV ($) | D6: IRR (%) | E6: Equity Multiple
B7: 5-Year | C7: =Summary!C9 -> 1.3417091e+08 | D7: =Summary!C10 -> 0.51843884 | E7: =Summary!C11 -> 6.3885436
B8: 8-Year | C8: =Summary!D9 -> 1.3656365e+08 | D8: =Summary!D10 -> 0.38501004 | E8: =Summary!D11 -> 8.0029233
B9: 10-Year | C9: =Summary!E9 -> 1.3953489e+08 | D9: =Summary!E10 -> 0.34672466 | E9: =Summary!E11 -> 9.2910075
B10: 12-Year | C10: =Summary!F9 -> 1.422146e+08 | D10: =Summary!F10 -> 0.32359078 | E10: =Summary!F11 -> 10.687539
B11: 20-Year | C11: =Summary!G9 -> 1.4849626e+08 | D11: =Summary!G10 -> 0.2870861 | E11: =Summary!G11 -> 17.318415
B16: Data Block 2: Cumulative Cash Flow by Year (each Holding Period)
B17: Year | C17: 5-Year | D17: 8-Year | E17: 10-Year | F17: 12-Year | G17: 20-Year
B18: 0 | C18: =Scenarios!C12 -> -42000000 | D18: =Scenarios!C23 -> -42000000 | E18: =Scenarios!C34 -> -42000000 | F18: =Scenarios!C45 -> -42000000 | G18: =Scenarios!C56 -> -42000000
B19: 1 | C19: =Scenarios!D12 -> -35742647 | D19: =Scenarios!D23 -> -35742647 | E19: =Scenarios!D34 -> -35742647 | F19: =Scenarios!D45 -> -35742647 | G19: =Scenarios!D56 -> -35742647
B20: 2 | C20: =Scenarios!E12 -> -27005954 | D20: =Scenarios!E23 -> -27005954 | E20: =Scenarios!E34 -> -27005954 | F20: =Scenarios!E45 -> -27005954 | G20: =Scenarios!E56 -> -27005954
B21: 3 | C21: =Scenarios!F12 -> -15557462 | D21: =Scenarios!F23 -> -15557462 | E21: =Scenarios!F34 -> -15557462 | F21: =Scenarios!F45 -> -15557462 | G21: =Scenarios!F56 -> -15557462
B22: 4 | C22: =Scenarios!G12 -> -2240477.1 | D22: =Scenarios!G23 -> -2240477.1 | E22: =Scenarios!G34 -> -2240477.1 | F22: =Scenarios!G45 -> -2240477.1 | G22: =Scenarios!G56 -> -2240477.1
B23: 5 | C23: =Scenarios!H12 -> 2.2631883e+08 | D23: =Scenarios!H23 -> 11649851 | E23: =Scenarios!H34 -> 11649851 | F23: =Scenarios!H45 -> 11649851 | G23: =Scenarios!H56 -> 11649851
B24: 6 | C24: =Scenarios!I12 -> 2.2631883e+08 | D24: =Scenarios!I23 -> 26136599 | E24: =Scenarios!I34 -> 26136599 | F24: =Scenarios!I45 -> 26136599 | G24: =Scenarios!I56 -> 26136599
B25: 7 | C25: =Scenarios!J12 -> 2.2631883e+08 | D25: =Scenarios!J23 -> 41243738 | E25: =Scenarios!J34 -> 41243738 | F25: =Scenarios!J45 -> 41243738 | G25: =Scenarios!J56 -> 41243738
B26: 8 | C26: =Scenarios!K12 -> 2.2631883e+08 | D26: =Scenarios!K23 -> 2.9412278e+08 | E26: =Scenarios!K34 -> 51457962 | F26: =Scenarios!K45 -> 51457962 | G26: =Scenarios!K56 -> 51457962
B27: 9 | C27: =Scenarios!L12 -> 2.2631883e+08 | D27: =Scenarios!L23 -> 2.9412278e+08 | E27: =Scenarios!L34 -> 67881530 | F27: =Scenarios!L45 -> 67881530 | G27: =Scenarios!L56 -> 67881530
B28: 10 | C28: =Scenarios!M12 -> 2.2631883e+08 | D28: =Scenarios!M23 -> 2.9412278e+08 | E28: =Scenarios!M34 -> 3.4822232e+08 | F28: =Scenarios!M45 -> 85003096 | G28: =Scenarios!M56 -> 85003096
B29: 11 | C29: =Scenarios!N12 -> 2.2631883e+08 | D29: =Scenarios!N23 -> 2.9412278e+08 | E29: =Scenarios!N34 -> 3.4822232e+08 | F29: =Scenarios!N45 -> 1.0285055e+08 | G29: =Scenarios!N56 -> 1.0285055e+08
B30: 12 | C30: =Scenarios!O12 -> 2.2631883e+08 | D30: =Scenarios!O23 -> 2.9412278e+08 | E30: =Scenarios!O34 -> 3.4822232e+08 | F30: =Scenarios!O45 -> 4.0687666e+08 | G30: =Scenarios!O56 -> 1.2145286e+08
B31: 13 | C31: =Scenarios!P12 -> 2.2631883e+08 | D31: =Scenarios!P23 -> 2.9412278e+08 | E31: =Scenarios!P34 -> 3.4822232e+08 | F31: =Scenarios!P45 -> 4.0687666e+08 | G31: =Scenarios!P56 -> 1.408401e+08
B32: 14 | C32: =Scenarios!Q12 -> 2.2631883e+08 | D32: =Scenarios!Q23 -> 2.9412278e+08 | E32: =Scenarios!Q34 -> 3.4822232e+08 | F32: =Scenarios!Q45 -> 4.0687666e+08 | G32: =Scenarios!Q56 -> 1.6104351e+08
B33: 15 | C33: =Scenarios!R12 -> 2.2631883e+08 | D33: =Scenarios!R23 -> 2.9412278e+08 | E33: =Scenarios!R34 -> 3.4822232e+08 | F33: =Scenarios!R45 -> 4.0687666e+08 | G33: =Scenarios!R56 -> 1.8209552e+08
B34: 16 | C34: =Scenarios!S12 -> 2.2631883e+08 | D34: =Scenarios!S23 -> 2.9412278e+08 | E34: =Scenarios!S34 -> 3.4822232e+08 | F34: =Scenarios!S45 -> 4.0687666e+08 | G34: =Scenarios!S56 -> 1.9678497e+08
