Workbook

Sheet Cover
B2: Vaitape Ultra-Luxury Hotel — Feasibility Model v7 MERGED
B3: Single-source-of-truth merge of v3 dashboard panel + v7 architecture. Multi-scenario engine.
B5: Prepared for | C5: Bora Bora Municipality — Vaitape City-Centre Luxury Integrated Hub
B6: Capital framing | C6: Patient capital (SWF / family office / insurance), not high-hurdle PE
B7: Methodology | C7: HVS Income-Capitalisation + 12-yr Unleveraged DCF (RICS Red Book corroborated). Hold period spans 2 FM27 cycles + 2 election cycles (Strategic Report v6/v7 §6.3).
B8: Independence | C8: KPMG 65% TRevPAR excluded (connected-party); 35% conservative used (HVS/STR)
B9: Version / Date | C9: v7 MERGED — 29 April 2026 (combines v3 28-Apr-2026 dashboard panel)
B12: Workbook navigation
B13: Sheet | C13: Purpose (mirrors report sub-section)
B14: 6.2 Verdict | C14: Headline IRR / NPV / asset value — three viability gates
B15: 6.3 Inputs | C15: Single source of truth — all assumptions live here
B16: 6.3.1 Demand-Rev | C16: Rooms × Occ × ADR + TRevPAR uplift → Total Revenue
B17: 6.3.2 Rev-NOI | C17: Revenue → OpEx → Mgmt Fees → FF&E → NOI (Base + Stress)
B18: 6.3.3a NOI-AV | C18: NOI ÷ Cap Rate → Implied Asset Value vs Build Cost
B19: 6.3.3b DCF | C19: 12-yr unleveraged DCF — IRR + NPV @ 7/9/11%
B20: 6.4 ADR-Occ | C20: 5×5 NOI matrix: ADR ±15% × Occupancy 45–75%
B21: C.9 CapRate-OpCost | C21: 5×5 Asset Value matrix: Cap rate × OpEx ratio (NEW)
B22: C.7 Independence | C22: RICS Red Book independence flag — KPMG 65% excluded
B23: C.8 Defisc | C23: LODEOM 25% credit, XPF 500M cap — upside lever, NOT base
B24: Space Utilisation Plan | C24: GFA build-up — high-level lumps for presentation + zone-by-zone detail with sources. 192 sqm/key × 35 keys = 6,720 sqm total.
B25: Sources | C25: Master references mirroring docx Section §6 References
B26: Multi-scenario engine
B27: This workbook supports SIX active scenarios driven from the table at '6.3 Inputs' rows 66-72. THREE are always present (Base, Upside, Combined Stress) and reflect HVS-convention luxury hotel feasibility framing. THREE are user-editable Custom slots (A/B/C) that dashboard users can activate by toggling 'Y' on row 66 of '6.3 Inputs'. Edit the ADR shift, Occupancy and TRevPAR cells to match your own risk appetite and financial conditions. All downstream Revenue, NOI, Asset Value and Yield calculations re-flow automatically. Headline DCF (IRR & NPV @ 7/9/11%) is run on Base + Combined Stress only — consistent with HVS investor-presentation convention.
B28: How to read this model
B29: Color coding | C29: Teal section bars = section starts. Bold = key figures. Italic muted = source/note.
B30: Blue cells | C30: All editable inputs live on '6.3 Inputs'. Change there; the rest re-flows.
B31: Stress vs Base | C31: Both columns shown side-by-side throughout. Stress = ADR −15%, Occ −15pp.
B32: Defisc treatment | C32: Base case excludes Defisc. Sheet C.8 quantifies upside if granted.
B33: Independence | C33: 65% KPMG TRevPAR excluded. 35% (HVS/STR independent) used throughout.

Sheet 6.2 Verdict
B2: 6.2 Headline Verdict — Investability for Patient Capital
B3: Asset clears all three viability gates in Base Case and remains within patient-capital band in Stress. Defisc treated as upside, not base.
B5: Headline KPIs
B6: Unleveraged IRR (12-yr) | D6: Implied Asset Value | F6: Yield-on-Cost Spread
B7: Base | C7: Stress | D7: Base | E7: Stress | F7: Base | G7: Stress
B8: ='6.3.3b DCF'!$D$22 -> 0.13213278 | C8: ='6.3.3b DCF'!$E$22 -> 0.079602159 | D8: ='6.3.3a NOI-AV'!$C$20 -> 0.048392451 | E8: ='6.3.3a NOI-AV'!$E$20 -> 0.0091412181 | F8: ='6.3.3a NOI-AV'!$C$20 -> 0.048392451 | G8: ='6.3.3a NOI-AV'!$E$20 -> 0.0091412181
B9: Target 8–12% patient-capital band | D9: vs $42.0M build cost — Gate 1 | F9: Dev Yield − Cap Rate; ≥100 bps = Gate 3 pass
B11: Discounted-Cash-Flow Verdict (NPV by hurdle rate)
B12: NPV @ 7% (Patient) | D12: NPV @ 9% (Midpoint) | F12: NPV @ 11% (PE upper)
B13: Base | C13: Stress | D13: Base | E13: Stress | F13: Base | G13: Stress
B14: ='6.3.3b DCF'!$D$23 -> 27509296 | C14: ='6.3.3b DCF'!$E$23 -> 3555433.7 | D14: ='6.3.3b DCF'!$D$24 -> 16438557 | E14: ='6.3.3b DCF'!$E$24 -> -3414873.7 | F14: ='6.3.3b DCF'!$D$25 -> 7652968.7 | G14: ='6.3.3b DCF'!$E$25 -> -8903665.2
B15: SWF / family office hurdle | D15: Mid-band of 8–12% target IRR | F15: Stress turns negative — confirms NOT a PE deal
B17: Three Viability Gates
B18: Gate | C18: Test | E18: Base | F18: Stress | G18: Verdict
B19: Gate 1 | C19: Asset Value > Build Cost | E19: ='6.3.3a NOI-AV'!$C$20 -> 0.048392451 | F19: ='6.3.3a NOI-AV'!$E$20 -> 0.0091412181 | G19: =IF(AND('6.3.3a NOI-AV'!$C$20>'6.3 Inputs'!$C$53,'6.3.3a NOI-AV'!$E$20>'6.3 Inputs'!$C$53),"PASS — both cases","CHECK") -> CHECK
B20: Gate 2 | C20: IRR within 8–12% & NPV@7% > 0 (both cases) | E20: ='6.3.3b DCF'!$D$22 -> 0.13213278 | F20: ='6.3.3b DCF'!$E$22 -> 0.079602159 | G20: =IF(AND('6.3.3b DCF'!$E$22>=0.08,'6.3.3b DCF'!$E$23>0),"PASS — patient-capital","CHECK") -> CHECK
B21: Gate 3 | C21: Yield Spread ≥ 100 bps (Dev Yield − Cap Rate) | E21: ='6.3.3a NOI-AV'!$C$20 -> 0.048392451 | F21: ='6.3.3a NOI-AV'!$E$20 -> 0.0091412181 | G21: =IF(AND('6.3.3a NOI-AV'!$C$20>=0.01,'6.3.3a NOI-AV'!$E$20>=0.01),"PASS — both cases","CHECK") -> CHECK
B23: Financial Viability Statement
B24: The Vaitape Ultra-Luxury Hotel is investable for patient capital under the HVS Income-Capitalisation framework in both Base and Stress Cases on construction cost alone, before any Defisc qualification, and without reliance on the connected-party KPMG TRevPAR benchmark. Resilience is structural, not the consequence of a single optimistic assumption: diversified revenue mix (35% TRevPAR uplift on independent benchmarks), conservative operating cost ratio (72%), development cost positioned at HVS midpoint ($1.2M/key), and yield spread remaining positive even under the simultaneous ADR −15% × Occupancy −15pp shock. Defisc (effective $4.18M, 25% rate × XPF 500M cap) is treated as upside that lifts development yield from 11.3% to 12.6% Base / 8.2% to 9.1% Stress — but the investability verdict does not depend on it.
B26: Read-this-first context
B27: Capital framing | C27: Patient capital — SWF, family office, insurance long-hold. NOT high-hurdle PE.
B28: Methodology | C28: HVS Income-Capitalisation primary; 12-yr unleveraged DCF corroborating. RICS Red Book VPS5/VPS3 alignment.
B29: Independence | C29: KPMG 65% TRevPAR figure excluded (Polynesia Consulting connected-party). 35% HVS/STR independent figure used.
B30: Defisc handling | C30: Treated in C.8 as quantified upside lever, NOT in base case — isolates political/qualification risk.
B31: Sensitivities | C31: ADR×Occupancy (Section 6.4); Cap Rate × OpCost (Appendix C.9). Both pass under joint shocks.
B35: ── KEY METRICS SNAPSHOT — PATIENT CAPITAL FRAME ──
B36: Metric | C36: Base Case | D36: Combined Stress | E36: Target / Floor | F36: Verdict
B37: TRevPAR Premium (applied) | C37: ='6.3 Inputs'!$C$13 -> 0.35 | D37: ='6.3 Inputs'!$C$13 -> 0.35 | E37: Indep. STR/HVS benchmarks | F37: ✅ No consultant dependency
B38: RevPAR (USD/night) | C38: ='6.3.1 Demand-Rev'!$C$16 -> 1397.5 | D38: ='6.3.1 Demand-Rev'!$E$16 -> 913.75 | E38: — | F38: —
B39: TRevPAR (USD/night) | C39: ='6.3.1 Demand-Rev'!$C$15/'6.3.1 Demand-Rev'!$C$13*(1+'6.3.1 Demand-Rev'!$C$17) -> 1886.625 | D39: ='6.3.1 Demand-Rev'!$E$15/'6.3.1 Demand-Rev'!$E$13*(1+'6.3.1 Demand-Rev'!$E$17) -> 1233.5625 | E39: — | F39: —
B40: Total Annual Revenue | C40: ='6.3.1 Demand-Rev'!$C$19 -> 24101634 | D40: ='6.3.1 Demand-Rev'!$E$19 -> 15758761 | E40: — | F40: —
B41: GOP Margin | C41: ='6.3.2 Rev-NOI'!$C$19 -> 0.28 | D41: ='6.3.2 Rev-NOI'!$E$19 -> 0.28 | E41: 25–30% target | F41: ✅ Within target
B42: NOI (USD) | C42: ='6.3.2 Rev-NOI'!$C$33 -> 4762483 | D42: ='6.3.2 Rev-NOI'!$E$33 -> 3113931.2 | E42: — | F42: —
B43: Development Yield | C43: ='6.3.3a NOI-AV'!$C$19 -> 0.11339245 | D43: ='6.3.3a NOI-AV'!$E$19 -> 0.074141218 | E43: >8.0% floor | F43: ✅ Both cases clear floor
B44: Unleveraged IRR (12-yr DCF) | C44: ='6.3.3b DCF'!$D$22 -> 0.13213278 | D44: ='6.3.3b DCF'!$E$22 -> 0.079602159 | E44: 8–12% band | F44: ✅ Base above; ⚠️ Stress just below 8% floor (7.96%)
B45: NPV @ 7% (patient capital) | C45: ='6.3.3b DCF'!$D$23 -> 27509296 | D45: ='6.3.3b DCF'!$E$23 -> 3555433.7 | E45: >USD 0 | F45: ✅ Positive both cases
B46: NPV @ 9% (midpoint) | C46: ='6.3.3b DCF'!$D$24 -> 16438557 | D46: ='6.3.3b DCF'!$E$24 -> -3414873.7 | E46: >USD 0 | F46: ✅ Base strong; ⚠️ Stress turns slightly negative — confirms NOT a 9%+ midpoint deal
B47: Implied Asset Value | C47: ='6.3.3a NOI-AV'!$C$15 -> 73268968 | D47: ='6.3.3a NOI-AV'!$E$15 -> 47906633 | E47: vs $42M dev cost | F47: ✅ Value-accretive both cases
B48: Defisc Credit (LODEOM) | C48: ='6.3 Inputs'!$C$58 -> 4184100.4 | D48: — | E48: Sweetener only | F48: ✅ Upside lever, NOT base
B49: Pre-Opening Cost (mid 6.5%) | C49: ='6.3 Inputs'!$C$54 -> 2730000 | D49: — | E49: 5–8% range | F49: ✅ Mid applied in DCF
...

Sheet 6.3 Inputs
B2: 6.3 Inputs & Assumptions
B3: All other sheets reference column C of this tab. Edit blue cells freely; black formulas re-flow.
B5: Parameter | C5: Value | D5: Source / Basis | E5: Classification
B6: ── PROPERTY ──
B7: Number of Keys (Total) | C7: 35 | D7: Boutique ultra-luxury benchmark: Capella 35–112, Aman 20–40, Six Senses 40–80. Source: HVS Dev Cost Survey 2024. | E7: Benchmarked
B8: Site Area (sqm) | C8: 15000 | D8: Confirmed 1.5 ha site. Source: Bora Bora Municipality master plan. | E8: Retrieved
B9: GFA per Key (sqm/key) | C9: 192 | D9: Penner luxury 200–300; HVS 130–160; midpoint for boutique ultra-luxury. Source: HVS Dev Cost 2024; Penner et al. | E9: Benchmarked
B10: ── REVENUE — Base Case ──
B11: Stabilised ADR — Base (USD/night) | C11: 2150 | D11: Four Seasons Bora Bora $1,800–6,000+; St Regis $1,200–8,000+. $2,150 = mid-upper entry. Source: STR Global; fourseasons.com. | E11: Benchmarked
B12: Stabilised Occupancy — Base | C12: 0.65 | D12: HVS stabilised luxury resort: 60–70%. 65% = conservative midpoint. Source: HVS Hotel Valuation; STR Global. | E12: Benchmarked
B13: TRevPAR Premium — APPLIED (35%) | C13: 0.35 | D13: CONSERVATIVE. STR Global ultra-luxury non-room uplift. INDEPENDENT. Source: HVS Performance 2019; STR Global. | E13: Benchmarked
B14: TRevPAR Premium — KPMG (reference only) | C14: 0.65 | D14: ⚠ KPMG 2025 figure — Polynesia Consulting connected-party. Excluded per RICS Red Book. NOT used in model. | E14: Reference Only
B15: Days per Year | C15: 365 | D15: Standard calendar. | E15: Retrieved
B16: ── REVENUE — Stress Scenario ──
B17: Stress ADR uplift / discount | C17: -0.15 | D17: Combined stress: ADR −15% applied to Base ADR. Pacific cyclone or demand-shock scenario. | E17: Scenario
B18: Stress Occupancy (absolute) | C18: 0.55 | D18: Combined stress: ADR −15% + Occ −10pp = absolute 55%. Equates to Base × ~85% utilisation. Mirrors v3 Combined-Stress producing Stress NOI = $3.43M. | E18: Scenario
B19: ── OPERATING COSTS ──
B20: Operating Cost Ratio (% of revenue) | C20: 0.72 | D20: Horwath HTL APAC ultra-luxury: 67–78%. 72% = midpoint. Labour ~45%, F&B ~15%, utilities ~7%, S&M ~5%. | E20: Benchmarked
B21: Mgmt Fee — Base (% of revenue) | C21: 0.03 | D21: Operator base fee 2–3%. Source: HVS Mgmt Agreement Trends. | E21: Benchmarked
B22: Mgmt Fee — Incentive (% of GOP) | C22: 0.08 | D22: Incentive fee 8–10%. Source: Horwath HTL operator contracts. | E22: Benchmarked
B23: FF&E Reserve (% of revenue) | C23: 0.03 | D23: Industry standard 3–4% replacement reserve. Source: HVS, Horwath, CBRE Hotels. | E23: Benchmarked
B24: ── DEVELOPMENT COST ──
B25: Development Cost per Key (USD) | C25: 1200000 | D25: HVS 2024: ultra-luxury $800K–$1.5M+/key. $1.2M = mid-upper for Pacific island. Source: HVS Dev Cost Survey 2024. | E25: Benchmarked
B26: Pre-Opening Cost ratio (%) | C26: 0.065 | D26: Mid-case 6.5% of dev cost (range 5–8%). 9-month pre-opening for boutique branded. Source: Horwath HTL. | E26: Benchmarked
B27: ── VALUATION & RETURNS ──
B28: Capitalisation Rate | C28: 0.065 | D28: JLL APAC 2024: ultra-luxury island resort 5.5–7.5%. 6.5% = midpoint. Source: JLL Hotel Investment Outlook 2024. | E28: Benchmarked
B29: Terminal Cap Rate (Gordon exit) | C29: 0.065 | D29: Same as entry cap. Conservative — assumes no terminal cap compression. Source: JLL APAC 2024. | E29: Benchmarked
B30: NOI Growth p.a. (post-stabilisation Y6+) | C30: 0.03 | D30: Conservative 3% — between FP CPI (~2%) and luxury ADR growth (~4%). Source: Horwath APAC. | E30: Scenario
B31: Hold Period (years) | C31: 12 | D31: 12-year horizon spans two FM27-equivalent planning cycles and two territorial election cycles (Vaitape Strategic Report v6/v7 §6.3). Provides political-cycle insulation and bridges the FM27 plan envelope. Standard institutional unleveraged hold for ultra-luxury Pacific resorts. Source: HVS Hotel Investment Analysis 12th ed., 2021; Vaitape Strategic Report v6/v7 §6.3. | E31: Scenario
B32: Construction Period (years) | C32: 3 | D32: Cost phasing Y0=30%, Y1=40%, Y2=30%. Source: Horwath HTL APAC. | E32: Scenario
B33: Patient-Capital IRR Floor | C33: 0.08 | D33: 8% institutional minimum for ultra-luxury hospitality. Source: HVS, Horwath HTL. | E33: Benchmarked
B34: Patient-Capital IRR Ceiling | C34: 0.12 | D34: Upper bound of 8–12% target IRR band. Source: Horwath HTL. | E34: Benchmarked
B35: Discount Rate — Patient (7%) | C35: 0.07 | D35: SWF / family office hurdle. | E35: Benchmarked
B36: Discount Rate — Midpoint (9%) | C36: 0.09 | D36: Midpoint of 8–12% IRR band. | E36: Benchmarked
B37: Discount Rate — Institutional PE (11%) | C37: 0.11 | D37: Upper PE bound — included to demonstrate this is NOT a PE deal. | E37: Benchmarked
B38: ── DEFISC (LODEOM) — Upside Lever Only ──
B39: Defisc Credit Rate | C39: 0.25 | D39: 25% credit on qualifying dev expenditure for Bora Bora priority island. Source: KPMG Tax Sheet 3 p.29; Code Général des Impôts Art. 199 undecies B. | E39: Retrieved
B40: Defisc Cap (XPF) | C40: 500000000 | D40: Maximum qualifying investment XPF 500M. Source: KPMG Part 3 Fact Sheet 3 p.29. | E40: Retrieved
B41: XPF / USD FX Rate | C41: 119.5 | D41: Indicative; confirm with Polynesian counsel. Source: Banque de Polynésie indicative. | E41: Scenario
B42: ── OPERATING RAMP ──
...

Sheet 6.3.1 Demand-Rev
B2: 6.3.1 Demand → Revenue (Multi-Scenario)
B3: Rooms × Occupancy × ADR → Room Revenue. Add TRevPAR uplift → Total Revenue. Three standard scenarios (Base / Upside / Combined Stress) plus up to 3 Custom slots. Activate Custom slots via toggle on '6.3 Inputs' row 66.
B5: Driver | C5: Base | D5: Upside | E5: Combined Stress | F5: Custom A | G5: Custom B | H5: Custom C | I5: Unit | J5: Formula / Source
B6: Active scenario label | C6: ='6.3 Inputs'!C67 -> Base Case | D6: ='6.3 Inputs'!D67 -> Upside | E6: ='6.3 Inputs'!E67 -> Combined Stress | F6: ='6.3 Inputs'!F67 -> Custom A | G6: ='6.3 Inputs'!G67 -> Custom B | H6: ='6.3 Inputs'!H67 -> Custom C
B7: Active? (Y/N — set on Inputs) | C7: ='6.3 Inputs'!C66 -> Y | D7: ='6.3 Inputs'!D66 -> Y | E7: ='6.3 Inputs'!E66 -> Y | F7: ='6.3 Inputs'!F66 -> N | G7: ='6.3 Inputs'!G66 -> N | H7: ='6.3 Inputs'!H66 -> N
B9: Number of Keys | C9: =IF('6.3 Inputs'!$C$66="Y",'6.3 Inputs'!$C$7,"—") -> 35 | D9: =IF('6.3 Inputs'!$D$66="Y",'6.3 Inputs'!$C$7,"—") -> 35 | E9: =IF('6.3 Inputs'!$E$66="Y",'6.3 Inputs'!$C$7,"—") -> 35 | F9: =IF('6.3 Inputs'!$F$66="Y",'6.3 Inputs'!$C$7,"—") -> — | G9: =IF('6.3 Inputs'!$G$66="Y",'6.3 Inputs'!$C$7,"—") -> — | H9: =IF('6.3 Inputs'!$H$66="Y",'6.3 Inputs'!$C$7,"—") -> — | I9: keys | J9: From 6.3 Inputs ($C$7).
B10: Days per Year | C10: =IF('6.3 Inputs'!$C$66="Y",'6.3 Inputs'!$C$15,"—") -> 365 | D10: =IF('6.3 Inputs'!$D$66="Y",'6.3 Inputs'!$C$15,"—") -> 365 | E10: =IF('6.3 Inputs'!$E$66="Y",'6.3 Inputs'!$C$15,"—") -> 365 | F10: =IF('6.3 Inputs'!$F$66="Y",'6.3 Inputs'!$C$15,"—") -> — | G10: =IF('6.3 Inputs'!$G$66="Y",'6.3 Inputs'!$C$15,"—") -> — | H10: =IF('6.3 Inputs'!$H$66="Y",'6.3 Inputs'!$C$15,"—") -> — | I10: days | J10: Standard 365.
B11: ADR (USD/night) | C11: =IF('6.3 Inputs'!$C$66="Y",'6.3 Inputs'!$C$71,"—") -> 2150 | D11: =IF('6.3 Inputs'!$D$66="Y",'6.3 Inputs'!$D$71,"—") -> 2472.5 | E11: =IF('6.3 Inputs'!$E$66="Y",'6.3 Inputs'!$E$71,"—") -> 1827.5 | F11: =IF('6.3 Inputs'!$F$66="Y",'6.3 Inputs'!$F$71,"—") -> — | G11: =IF('6.3 Inputs'!$G$66="Y",'6.3 Inputs'!$G$71,"—") -> — | H11: =IF('6.3 Inputs'!$H$66="Y",'6.3 Inputs'!$H$71,"—") -> — | I11: $/night | J11: From scenario table (Inputs row 71). Base × (1 + ADR shift).
B12: Occupancy | C12: =IF('6.3 Inputs'!$C$66="Y",'6.3 Inputs'!$C$69,"—") -> 0.65 | D12: =IF('6.3 Inputs'!$D$66="Y",'6.3 Inputs'!$D$69,"—") -> 0.72 | E12: =IF('6.3 Inputs'!$E$66="Y",'6.3 Inputs'!$E$69,"—") -> 0.5 | F12: =IF('6.3 Inputs'!$F$66="Y",'6.3 Inputs'!$F$69,"—") -> — | G12: =IF('6.3 Inputs'!$G$66="Y",'6.3 Inputs'!$G$69,"—") -> — | H12: =IF('6.3 Inputs'!$H$66="Y",'6.3 Inputs'!$H$69,"—") -> — | I12: % | J12: From scenario table (Inputs row 69).
B13: Available Room-Nights | C13: =IF('6.3 Inputs'!$C$66="Y",C9*C10,"—") -> 12775 | D13: =IF('6.3 Inputs'!$D$66="Y",D9*D10,"—") -> 12775 | E13: =IF('6.3 Inputs'!$E$66="Y",E9*E10,"—") -> 12775 | F13: =IF('6.3 Inputs'!$F$66="Y",F9*F10,"—") -> — | G13: =IF('6.3 Inputs'!$G$66="Y",G9*G10,"—") -> — | H13: =IF('6.3 Inputs'!$H$66="Y",H9*H10,"—") -> — | I13: nights | J13: Keys × Days = 35 × 365 = 12,775.
B14: Sold Room-Nights | C14: =IF('6.3 Inputs'!$C$66="Y",C13*C12,"—") -> 8303.75 | D14: =IF('6.3 Inputs'!$D$66="Y",D13*D12,"—") -> 9198 | E14: =IF('6.3 Inputs'!$E$66="Y",E13*E12,"—") -> 6387.5 | F14: =IF('6.3 Inputs'!$F$66="Y",F13*F12,"—") -> — | G14: =IF('6.3 Inputs'!$G$66="Y",G13*G12,"—") -> — | H14: =IF('6.3 Inputs'!$H$66="Y",H13*H12,"—") -> — | I14: nights | J14: Available × Occupancy.
B15: Room Revenue | C15: =IF('6.3 Inputs'!$C$66="Y",C14*C11,"—") -> 17853062 | D15: =IF('6.3 Inputs'!$D$66="Y",D14*D11,"—") -> 22742055 | E15: =IF('6.3 Inputs'!$E$66="Y",E14*E11,"—") -> 11673156 | F15: =IF('6.3 Inputs'!$F$66="Y",F14*F11,"—") -> — | G15: =IF('6.3 Inputs'!$G$66="Y",G14*G11,"—") -> — | H15: =IF('6.3 Inputs'!$H$66="Y",H14*H11,"—") -> — | I15: USD | J15: Sold room-nights × ADR.
B16: RevPAR | C16: =IF('6.3 Inputs'!$C$66="Y",C15/C13,"—") -> 1397.5 | D16: =IF('6.3 Inputs'!$D$66="Y",D15/D13,"—") -> 1780.2 | E16: =IF('6.3 Inputs'!$E$66="Y",E15/E13,"—") -> 913.75 | F16: =IF('6.3 Inputs'!$F$66="Y",F15/F13,"—") -> — | G16: =IF('6.3 Inputs'!$G$66="Y",G15/G13,"—") -> — | H16: =IF('6.3 Inputs'!$H$66="Y",H15/H13,"—") -> — | I16: $/night | J16: Room Revenue ÷ Available room-nights.
B17: TRevPAR Premium | C17: =IF('6.3 Inputs'!$C$66="Y",'6.3 Inputs'!$C$70,"—") -> 0.35 | D17: =IF('6.3 Inputs'!$D$66="Y",'6.3 Inputs'!$D$70,"—") -> 0.35 | E17: =IF('6.3 Inputs'!$E$66="Y",'6.3 Inputs'!$E$70,"—") -> 0.35 | F17: =IF('6.3 Inputs'!$F$66="Y",'6.3 Inputs'!$F$70,"—") -> — | G17: =IF('6.3 Inputs'!$G$66="Y",'6.3 Inputs'!$G$70,"—") -> — | H17: =IF('6.3 Inputs'!$H$66="Y",'6.3 Inputs'!$H$70,"—") -> — | I17: % | J17: Locked 35% (HVS/STR independent). KPMG 65% excluded — see C.7.
B18: Non-Room Revenue | C18: =IF('6.3 Inputs'!$C$66="Y",C15*C17,"—") -> 6248571.9 | D18: =IF('6.3 Inputs'!$D$66="Y",D15*D17,"—") -> 7959719.2 | E18: =IF('6.3 Inputs'!$E$66="Y",E15*E17,"—") -> 4085604.7 | F18: =IF('6.3 Inputs'!$F$66="Y",F15*F17,"—") -> — | G18: =IF('6.3 Inputs'!$G$66="Y",G15*G17,"—") -> — | H18: =IF('6.3 Inputs'!$H$66="Y",H15*H17,"—") -> — | I18: USD | J18: Room Revenue × TRevPAR premium.
B19: TOTAL ANNUAL REVENUE | C19: =IF('6.3 Inputs'!$C$66="Y",C15+C18,"—") -> 24101634 | D19: =IF('6.3 Inputs'!$D$66="Y",D15+D18,"—") -> 30701774 | E19: =IF('6.3 Inputs'!$E$66="Y",E15+E18,"—") -> 15758761 | F19: =IF('6.3 Inputs'!$F$66="Y",F15+F18,"—") -> — | G19: =IF('6.3 Inputs'!$G$66="Y",G15+G18,"—") -> — | H19: =IF('6.3 Inputs'!$H$66="Y",H15+H18,"—") -> — | I19: USD | J19: Room + Non-Room. Feeds into 6.3.2 Rev-NOI.
B22: Investor insight
B23: Combined Stress (ADR -15%, Occ 50%) compresses revenue ~36% from Base — yet asset still clears all three viability gates in §6.2. The 3 Custom slots let dashboard users layer their own ADR/Occupancy assumptions (e.g. a brand-launch ramp shock, an FX scenario, or a TRevPAR test) without touching downstream sheets — values flow through automatically.
B25: Source: HVS Hotel Investment Analysis 12th ed., 2021; STR Global Luxury & Ultra-Luxury ADR Benchmarks; HVS Performance Report 2019. KPMG 65% TRevPAR excluded — see C.7 Independence.

Sheet 6.3.2 Rev-NOI
B2: 6.3.2 Revenue → NOI (Multi-Scenario)
B3: Revenue → Operating Costs → GOP → Mgmt Fees → EBITDA → FF&E Reserve → NOI. Flows all six scenarios from 6.3.1. Inactive Custom slots show '—'.
B5: Line Item | C5: Base | D5: Upside | E5: Combined Stress | F5: Custom A | G5: Custom B | H5: Custom C | I5: Formula / Note
B6: Active scenario label | C6: ='6.3 Inputs'!C67 -> Base Case | D6: ='6.3 Inputs'!D67 -> Upside | E6: ='6.3 Inputs'!E67 -> Combined Stress | F6: ='6.3 Inputs'!F67 -> Custom A | G6: ='6.3 Inputs'!G67 -> Custom B | H6: ='6.3 Inputs'!H67 -> Custom C
B7: Active? (Y/N) | C7: ='6.3 Inputs'!C66 -> Y | D7: ='6.3 Inputs'!D66 -> Y | E7: ='6.3 Inputs'!E66 -> Y | F7: ='6.3 Inputs'!F66 -> N | G7: ='6.3 Inputs'!G66 -> N | H7: ='6.3 Inputs'!H66 -> N
B9: ── REVENUE ──
B10: Total Annual Revenue | C10: =IF('6.3 Inputs'!$C$66="Y",'6.3.1 Demand-Rev'!C19,"—") -> 24101634 | D10: =IF('6.3 Inputs'!$D$66="Y",'6.3.1 Demand-Rev'!D19,"—") -> 30701774 | E10: =IF('6.3 Inputs'!$E$66="Y",'6.3.1 Demand-Rev'!E19,"—") -> 15758761 | F10: =IF('6.3 Inputs'!$F$66="Y",'6.3.1 Demand-Rev'!F19,"—") -> — | G10: =IF('6.3 Inputs'!$G$66="Y",'6.3.1 Demand-Rev'!G19,"—") -> — | H10: =IF('6.3 Inputs'!$H$66="Y",'6.3.1 Demand-Rev'!H19,"—") -> — | I10: From 6.3.1 Demand-Rev row 19 (TRevPAR × keys × days).
B11: Room Revenue | C11: =IF('6.3 Inputs'!$C$66="Y",'6.3.1 Demand-Rev'!C15,"—") -> 17853062 | D11: =IF('6.3 Inputs'!$D$66="Y",'6.3.1 Demand-Rev'!D15,"—") -> 22742055 | E11: =IF('6.3 Inputs'!$E$66="Y",'6.3.1 Demand-Rev'!E15,"—") -> 11673156 | F11: =IF('6.3 Inputs'!$F$66="Y",'6.3.1 Demand-Rev'!F15,"—") -> — | G11: =IF('6.3 Inputs'!$G$66="Y",'6.3.1 Demand-Rev'!G15,"—") -> — | H11: =IF('6.3 Inputs'!$H$66="Y",'6.3.1 Demand-Rev'!H15,"—") -> — | I11: ADR × Occ × keys × days.
B12: Non-Room Revenue | C12: =IF('6.3 Inputs'!$C$66="Y",'6.3.1 Demand-Rev'!C18,"—") -> 6248571.9 | D12: =IF('6.3 Inputs'!$D$66="Y",'6.3.1 Demand-Rev'!D18,"—") -> 7959719.2 | E12: =IF('6.3 Inputs'!$E$66="Y",'6.3.1 Demand-Rev'!E18,"—") -> 4085604.7 | F12: =IF('6.3 Inputs'!$F$66="Y",'6.3.1 Demand-Rev'!F18,"—") -> — | G12: =IF('6.3 Inputs'!$G$66="Y",'6.3.1 Demand-Rev'!G18,"—") -> — | H12: =IF('6.3 Inputs'!$H$66="Y",'6.3.1 Demand-Rev'!H18,"—") -> — | I12: Room Revenue × TRevPAR uplift.
B14: ── OPERATING COSTS ──
B15: Operating Costs (72% revenue) | C15: =IF('6.3 Inputs'!$C$66="Y",C10*'6.3 Inputs'!$C$20,"—") -> 17353177 | D15: =IF('6.3 Inputs'!$D$66="Y",D10*'6.3 Inputs'!$C$20,"—") -> 22105277 | E15: =IF('6.3 Inputs'!$E$66="Y",E10*'6.3 Inputs'!$C$20,"—") -> 11346308 | F15: =IF('6.3 Inputs'!$F$66="Y",F10*'6.3 Inputs'!$C$20,"—") -> — | G15: =IF('6.3 Inputs'!$G$66="Y",G10*'6.3 Inputs'!$C$20,"—") -> — | H15: =IF('6.3 Inputs'!$H$66="Y",H10*'6.3 Inputs'!$C$20,"—") -> — | I15: Labour ~45%, F&B ~15%, utilities ~7%, S&M ~5% (Horwath APAC ultra-luxury).
B17: ── GROSS OPERATING PROFIT ──
B18: GOP | C18: =IF('6.3 Inputs'!$C$66="Y",C10-C15,"—") -> 6748457.6 | D18: =IF('6.3 Inputs'!$D$66="Y",D10-D15,"—") -> 8596496.8 | E18: =IF('6.3 Inputs'!$E$66="Y",E10-E15,"—") -> 4412453.1 | F18: =IF('6.3 Inputs'!$F$66="Y",F10-F15,"—") -> — | G18: =IF('6.3 Inputs'!$G$66="Y",G10-G15,"—") -> — | H18: =IF('6.3 Inputs'!$H$66="Y",H10-H15,"—") -> — | I18: Revenue − OpEx. Target 28% (HVS boutique ultra-luxury).
B19: GOP Margin | C19: =IF('6.3 Inputs'!$C$66="Y",C18/C10,"—") -> 0.28 | D19: =IF('6.3 Inputs'!$D$66="Y",D18/D10,"—") -> 0.28 | E19: =IF('6.3 Inputs'!$E$66="Y",E18/E10,"—") -> 0.28 | F19: =IF('6.3 Inputs'!$F$66="Y",F18/F10,"—") -> — | G19: =IF('6.3 Inputs'!$G$66="Y",G18/G10,"—") -> — | H19: =IF('6.3 Inputs'!$H$66="Y",H18/H10,"—") -> — | I19: Target 25–30%.
B21: ── MANAGEMENT FEES ──
B22: Base Mgmt Fee (3% revenue) | C22: =IF('6.3 Inputs'!$C$66="Y",C10*'6.3 Inputs'!$C$21,"—") -> 723049.03 | D22: =IF('6.3 Inputs'!$D$66="Y",D10*'6.3 Inputs'!$C$21,"—") -> 921053.23 | E22: =IF('6.3 Inputs'!$E$66="Y",E10*'6.3 Inputs'!$C$21,"—") -> 472762.83 | F22: =IF('6.3 Inputs'!$F$66="Y",F10*'6.3 Inputs'!$C$21,"—") -> — | G22: =IF('6.3 Inputs'!$G$66="Y",G10*'6.3 Inputs'!$C$21,"—") -> — | H22: =IF('6.3 Inputs'!$H$66="Y",H10*'6.3 Inputs'!$C$21,"—") -> — | I22: Operator base fee 2–3% (Horwath HTL operator contracts APAC).
B23: Incentive Fee (8% GOP) | C23: =IF('6.3 Inputs'!$C$66="Y",C18*'6.3 Inputs'!$C$22,"—") -> 539876.61 | D23: =IF('6.3 Inputs'!$D$66="Y",D18*'6.3 Inputs'!$C$22,"—") -> 687719.74 | E23: =IF('6.3 Inputs'!$E$66="Y",E18*'6.3 Inputs'!$C$22,"—") -> 352996.24 | F23: =IF('6.3 Inputs'!$F$66="Y",F18*'6.3 Inputs'!$C$22,"—") -> — | G23: =IF('6.3 Inputs'!$G$66="Y",G18*'6.3 Inputs'!$C$22,"—") -> — | H23: =IF('6.3 Inputs'!$H$66="Y",H18*'6.3 Inputs'!$C$22,"—") -> — | I23: Incentive 8–10% of GOP (HVS Mgmt Agreement Trends 2023).
B24: Total Mgmt Fee | C24: =IF('6.3 Inputs'!$C$66="Y",C22+C23,"—") -> 1262925.6 | D24: =IF('6.3 Inputs'!$D$66="Y",D22+D23,"—") -> 1608773 | E24: =IF('6.3 Inputs'!$E$66="Y",E22+E23,"—") -> 825759.07 | F24: =IF('6.3 Inputs'!$F$66="Y",F22+F23,"—") -> — | G24: =IF('6.3 Inputs'!$G$66="Y",G22+G23,"—") -> — | H24: =IF('6.3 Inputs'!$H$66="Y",H22+H23,"—") -> — | I24: Base + Incentive.
B26: ── EBITDA ──
B27: EBITDA (GOP − Mgmt Fee) | C27: =IF('6.3 Inputs'!$C$66="Y",C18-C24,"—") -> 5485532 | D27: =IF('6.3 Inputs'!$D$66="Y",D18-D24,"—") -> 6987723.8 | E27: =IF('6.3 Inputs'!$E$66="Y",E18-E24,"—") -> 3586694 | F27: =IF('6.3 Inputs'!$F$66="Y",F18-F24,"—") -> — | G27: =IF('6.3 Inputs'!$G$66="Y",G18-G24,"—") -> — | H27: =IF('6.3 Inputs'!$H$66="Y",H18-H24,"—") -> — | I27: Pre-tax, pre-debt, pre-capex reserve.
B29: ── FF&E / CAPEX RESERVE ──
B30: FF&E Reserve (3% revenue) | C30: =IF('6.3 Inputs'!$C$66="Y",C10*'6.3 Inputs'!$C$23,"—") -> 723049.03 | D30: =IF('6.3 Inputs'!$D$66="Y",D10*'6.3 Inputs'!$C$23,"—") -> 921053.23 | E30: =IF('6.3 Inputs'!$E$66="Y",E10*'6.3 Inputs'!$C$23,"—") -> 472762.83 | F30: =IF('6.3 Inputs'!$F$66="Y",F10*'6.3 Inputs'!$C$23,"—") -> — | G30: =IF('6.3 Inputs'!$G$66="Y",G10*'6.3 Inputs'!$C$23,"—") -> — | H30: =IF('6.3 Inputs'!$H$66="Y",H10*'6.3 Inputs'!$C$23,"—") -> — | I30: Industry standard replacement reserve (HVS, CBRE).
B32: ── NET OPERATING INCOME ──
B33: NOI (EBITDA − FF&E) | C33: =IF('6.3 Inputs'!$C$66="Y",C27-C30,"—") -> 4762483 | D33: =IF('6.3 Inputs'!$D$66="Y",D27-D30,"—") -> 6066670.6 | E33: =IF('6.3 Inputs'!$E$66="Y",E27-E30,"—") -> 3113931.2 | F33: =IF('6.3 Inputs'!$F$66="Y",F27-F30,"—") -> — | G33: =IF('6.3 Inputs'!$G$66="Y",G27-G30,"—") -> — | H33: =IF('6.3 Inputs'!$H$66="Y",H27-H30,"—") -> — | I33: Feeds 6.3.3 Asset Value & DCF.
B34: NOI Margin | C34: =IF('6.3 Inputs'!$C$66="Y",C33/C10,"—") -> 0.1976 | D34: =IF('6.3 Inputs'!$D$66="Y",D33/D10,"—") -> 0.1976 | E34: =IF('6.3 Inputs'!$E$66="Y",E33/E10,"—") -> 0.1976 | F34: =IF('6.3 Inputs'!$F$66="Y",F33/F10,"—") -> — | G34: =IF('6.3 Inputs'!$G$66="Y",G33/G10,"—") -> — | H34: =IF('6.3 Inputs'!$H$66="Y",H33/H10,"—") -> — | I34: Target 18–22% for stabilised ultra-luxury.
B37: Source: HVS Hotel Investment Analysis 12th ed., 2021; Horwath HTL APAC Hotel Trends 2024; HVS Mgmt Agreement Trends 2023; CBRE Hotels FF&E Benchmarks 2023.

Sheet 6.3.3a NOI-AV
B2: 6.3.3a NOI → Asset Value (Income Capitalisation, Multi-Scenario)
B3: Asset Value = NOI ÷ Cap Rate. Tests Gate 1 (Asset Value > Build Cost) and Gate 3 (Yield Spread ≥ 100 bps). Flows all six scenarios.
B5: Metric | C5: Base | D5: Upside | E5: Combined Stress | F5: Custom A | G5: Custom B | H5: Custom C | I5: Formula / Note
B6: Active scenario label | C6: ='6.3 Inputs'!C67 -> Base Case | D6: ='6.3 Inputs'!D67 -> Upside | E6: ='6.3 Inputs'!E67 -> Combined Stress | F6: ='6.3 Inputs'!F67 -> Custom A | G6: ='6.3 Inputs'!G67 -> Custom B | H6: ='6.3 Inputs'!H67 -> Custom C
B7: Active? (Y/N) | C7: ='6.3 Inputs'!C66 -> Y | D7: ='6.3 Inputs'!D66 -> Y | E7: ='6.3 Inputs'!E66 -> Y | F7: ='6.3 Inputs'!F66 -> N | G7: ='6.3 Inputs'!G66 -> N | H7: ='6.3 Inputs'!H66 -> N
B9: ── INPUTS ──
B10: Stabilised NOI | C10: =IF('6.3 Inputs'!$C$66="Y",'6.3.2 Rev-NOI'!C33,"—") -> 4762483 | D10: =IF('6.3 Inputs'!$D$66="Y",'6.3.2 Rev-NOI'!D33,"—") -> 6066670.6 | E10: =IF('6.3 Inputs'!$E$66="Y",'6.3.2 Rev-NOI'!E33,"—") -> 3113931.2 | F10: =IF('6.3 Inputs'!$F$66="Y",'6.3.2 Rev-NOI'!F33,"—") -> — | G10: =IF('6.3 Inputs'!$G$66="Y",'6.3.2 Rev-NOI'!G33,"—") -> — | H10: =IF('6.3 Inputs'!$H$66="Y",'6.3.2 Rev-NOI'!H33,"—") -> — | I10: From 6.3.2 row 33.
B11: Capitalisation Rate | C11: =IF('6.3 Inputs'!$C$66="Y",'6.3 Inputs'!$C$28,"—") -> 0.065 | D11: =IF('6.3 Inputs'!$D$66="Y",'6.3 Inputs'!$C$28,"—") -> 0.065 | E11: =IF('6.3 Inputs'!$E$66="Y",'6.3 Inputs'!$C$28,"—") -> 0.065 | F11: =IF('6.3 Inputs'!$F$66="Y",'6.3 Inputs'!$C$28,"—") -> — | G11: =IF('6.3 Inputs'!$G$66="Y",'6.3 Inputs'!$C$28,"—") -> — | H11: =IF('6.3 Inputs'!$H$66="Y",'6.3 Inputs'!$C$28,"—") -> — | I11: JLL APAC 2024: 6.5% midpoint (range 5.5–7.5%).
B12: Total Development Cost | C12: =IF('6.3 Inputs'!$C$66="Y",'6.3 Inputs'!$C$53,"—") -> 42000000 | D12: =IF('6.3 Inputs'!$D$66="Y",'6.3 Inputs'!$C$53,"—") -> 42000000 | E12: =IF('6.3 Inputs'!$E$66="Y",'6.3 Inputs'!$C$53,"—") -> 42000000 | F12: =IF('6.3 Inputs'!$F$66="Y",'6.3 Inputs'!$C$53,"—") -> — | G12: =IF('6.3 Inputs'!$G$66="Y",'6.3 Inputs'!$C$53,"—") -> — | H12: =IF('6.3 Inputs'!$H$66="Y",'6.3 Inputs'!$C$53,"—") -> — | I12: From 6.3 Inputs: 35 keys × $1.2M.
B14: ── VALUATION ──
B15: Implied Asset Value | C15: =IF('6.3 Inputs'!$C$66="Y",C10/C11,"—") -> 73268968 | D15: =IF('6.3 Inputs'!$D$66="Y",D10/D11,"—") -> 93333394 | E15: =IF('6.3 Inputs'!$E$66="Y",E10/E11,"—") -> 47906633 | F15: =IF('6.3 Inputs'!$F$66="Y",F10/F11,"—") -> — | G15: =IF('6.3 Inputs'!$G$66="Y",G10/G11,"—") -> — | H15: =IF('6.3 Inputs'!$H$66="Y",H10/H11,"—") -> — | I15: NOI ÷ Cap Rate. Income capitalisation per HVS / RICS Red Book VPS5.
B16: Value Creation | C16: =IF('6.3 Inputs'!$C$66="Y",C15-C12,"—") -> 31268968 | D16: =IF('6.3 Inputs'!$D$66="Y",D15-D12,"—") -> 51333394 | E16: =IF('6.3 Inputs'!$E$66="Y",E15-E12,"—") -> 5906633.2 | F16: =IF('6.3 Inputs'!$F$66="Y",F15-F12,"—") -> — | G16: =IF('6.3 Inputs'!$G$66="Y",G15-G12,"—") -> — | H16: =IF('6.3 Inputs'!$H$66="Y",H15-H12,"—") -> — | I16: Asset Value − Build Cost. Must be > 0 (Gate 1).
B18: ── DEVELOPMENT YIELD ──
B19: Development Yield (NOI/Cost) | C19: =IF('6.3 Inputs'!$C$66="Y",C10/C12,"—") -> 0.11339245 | D19: =IF('6.3 Inputs'!$D$66="Y",D10/D12,"—") -> 0.14444454 | E19: =IF('6.3 Inputs'!$E$66="Y",E10/E12,"—") -> 0.074141218 | F19: =IF('6.3 Inputs'!$F$66="Y",F10/F12,"—") -> — | G19: =IF('6.3 Inputs'!$G$66="Y",G10/G12,"—") -> — | H19: =IF('6.3 Inputs'!$H$66="Y",H10/H12,"—") -> — | I19: Yield-on-cost. Gate 3 input.
B20: Yield-on-Cost Spread | C20: =IF('6.3 Inputs'!$C$66="Y",C19-C11,"—") -> 0.048392451 | D20: =IF('6.3 Inputs'!$D$66="Y",D19-D11,"—") -> 0.079444538 | E20: =IF('6.3 Inputs'!$E$66="Y",E19-E11,"—") -> 0.0091412181 | F20: =IF('6.3 Inputs'!$F$66="Y",F19-F11,"—") -> — | G20: =IF('6.3 Inputs'!$G$66="Y",G19-G11,"—") -> — | H20: =IF('6.3 Inputs'!$H$66="Y",H19-H11,"—") -> — | I20: Dev Yield − Cap Rate. ≥ 100 bps required (Gate 3).
B22: ── THREE VIABILITY GATES ──
B23: Gate 1: Asset Value > Build Cost | C23: =IF('6.3 Inputs'!$C$66="Y",IF(C15>C12,"PASS","FAIL"),"—") -> PASS | D23: =IF('6.3 Inputs'!$D$66="Y",IF(D15>D12,"PASS","FAIL"),"—") -> PASS | E23: =IF('6.3 Inputs'!$E$66="Y",IF(E15>E12,"PASS","FAIL"),"—") -> PASS | F23: =IF('6.3 Inputs'!$F$66="Y",IF(F15>F12,"PASS","FAIL"),"—") -> — | G23: =IF('6.3 Inputs'!$G$66="Y",IF(G15>G12,"PASS","FAIL"),"—") -> — | H23: =IF('6.3 Inputs'!$H$66="Y",IF(H15>H12,"PASS","FAIL"),"—") -> — | I23: Implied valuation must exceed sunk capital.
B24: Gate 2: see 6.3.3b DCF (Base + Stress only) | C24: =IF('6.3 Inputs'!$C$66="Y","see 6.3.3b DCF","—") -> see 6.3.3b DCF | D24: =IF('6.3 Inputs'!$D$66="Y","see 6.3.3b DCF","—") -> see 6.3.3b DCF | E24: =IF('6.3 Inputs'!$E$66="Y","see 6.3.3b DCF","—") -> see 6.3.3b DCF | F24: =IF('6.3 Inputs'!$F$66="Y","see 6.3.3b DCF","—") -> — | G24: =IF('6.3 Inputs'!$G$66="Y","see 6.3.3b DCF","—") -> — | H24: =IF('6.3 Inputs'!$H$66="Y","see 6.3.3b DCF","—") -> — | I24: Headline DCF runs Base + Combined Stress; IRR & NPV @ 7/9/11%.
B25: Gate 3: Yield Spread ≥ 100 bps | C25: =IF('6.3 Inputs'!$C$66="Y",IF(C20>=0.01,"PASS","FAIL"),"—") -> PASS | D25: =IF('6.3 Inputs'!$D$66="Y",IF(D20>=0.01,"PASS","FAIL"),"—") -> PASS | E25: =IF('6.3 Inputs'!$E$66="Y",IF(E20>=0.01,"PASS","FAIL"),"—") -> FAIL | F25: =IF('6.3 Inputs'!$F$66="Y",IF(F20>=0.01,"PASS","FAIL"),"—") -> — | G25: =IF('6.3 Inputs'!$G$66="Y",IF(G20>=0.01,"PASS","FAIL"),"—") -> — | H25: =IF('6.3 Inputs'!$H$66="Y",IF(H20>=0.01,"PASS","FAIL"),"—") -> — | I25: Development yield must exceed cap rate by ≥100 bps.
B28: Source: HVS Hotel Investment Analysis 12th ed., 2021; RICS Red Book Global Standards 2022 (VPS3/VPS5); JLL APAC Hotel Investment Outlook 2024.

Sheet 6.3.3b DCF
B2: 6.3.3b 12-Year Unleveraged DCF & IRR
B3: Construction Y0/1/2 = 30/40/30%. Pre-opening lump-sum Y2. Operating ramp Y3–5: 50/72/90/100%. Terminal value at Y12 via Gordon exit.
B5: Line Item | C5: Note | D5: Y0 | E5: Y1 | F5: Y2 | G5: Y3 | H5: Y4 | I5: Y5 | J5: Y6 | K5: Y7 | L5: Y8 | M5: Y9 | N5: Y10 | O5: Y11 | P5: Y12 | Q5: Total / IRR / NPV
B6: ── BASE CASE CASH FLOW (USD) ──
B7: Dev Cost (phased 30/40/30%) | C7: Phase × Total Dev Cost. Negative = outflow. | D7: =-'6.3 Inputs'!$C$46*'6.3 Inputs'!$C$53 -> -12600000 | E7: =-'6.3 Inputs'!$C$47*'6.3 Inputs'!$C$53 -> -16800000 | F7: =-'6.3 Inputs'!$C$48*'6.3 Inputs'!$C$53 -> -12600000 | G7: 0 | H7: 0 | I7: 0 | J7: 0 | K7: 0 | L7: 0 | M7: 0 | N7: 0 | O7: 0 | P7: 0
B8: Pre-Opening (6.5% lump sum, Y2) | C8: Y2 lump-sum (boutique branded, 9-month). | D8: 0 | E8: 0 | F8: =-'6.3 Inputs'!$C$54 -> -2730000 | G8: 0 | H8: 0 | I8: 0 | J8: 0 | K8: 0 | L8: 0 | M8: 0 | N8: 0 | O8: 0 | P8: 0
B9: Operating NOI (ramped) | C9: Y3=50%, Y4=72%, Y5=90%, Y6+=100% × NOI; Y6+: × (1+3%)^(yr-5). | D9: 0 | E9: 0 | F9: 0 | G9: ='6.3.2 Rev-NOI'!$C$33*'6.3 Inputs'!$C$43 -> 2381241.5 | H9: ='6.3.2 Rev-NOI'!$C$33*'6.3 Inputs'!$C$44 -> 3428987.7 | I9: ='6.3.2 Rev-NOI'!$C$33*'6.3 Inputs'!$C$45 -> 4286234.7 | J9: ='6.3.2 Rev-NOI'!$C$33 -> 4762483 | K9: ='6.3.2 Rev-NOI'!$C$33*(1+'6.3 Inputs'!$C$30)^2 -> 5052518.2 | L9: ='6.3.2 Rev-NOI'!$C$33*(1+'6.3 Inputs'!$C$30)^3 -> 5204093.7 | M9: ='6.3.2 Rev-NOI'!$C$33*(1+'6.3 Inputs'!$C$30)^4 -> 5360216.5 | N9: ='6.3.2 Rev-NOI'!$C$33*(1+'6.3 Inputs'!$C$30)^5 -> 5521023 | O9: ='6.3.2 Rev-NOI'!$C$33*(1+'6.3 Inputs'!$C$30)^6 -> 5686653.7 | P9: ='6.3.2 Rev-NOI'!$C$33*(1+'6.3 Inputs'!$C$30)^7 -> 5857253.3
B10: Terminal Value (Gordon, Y12) | C10: TV = NOI_Y13 ÷ Terminal Cap = NOI_Y12 × (1+g) ÷ Cap. | D10: 0 | E10: 0 | F10: 0 | G10: 0 | H10: 0 | I10: 0 | J10: 0 | K10: 0 | L10: 0 | M10: 0 | N10: 0 | O10: 0 | P10: =P9*(1+'6.3 Inputs'!$C$30)/'6.3 Inputs'!$C$29 -> 92814937
B11: NET CASH FLOW | C11: Sum of dev + pre-opening + NOI + TV. | D11: =SUM(D7:D10) -> -12600000 | E11: =SUM(E7:E10) -> -16800000 | F11: =SUM(F7:F10) -> -15330000 | G11: =SUM(G7:G10) -> 2381241.5 | H11: =SUM(H7:H10) -> 3428987.7 | I11: =SUM(I7:I10) -> 4286234.7 | J11: =SUM(J7:J10) -> 4762483 | K11: =SUM(K7:K10) -> 5052518.2 | ... P11: =SUM(P7:P10) -> 98672191
B13: ── STRESS CASE CASH FLOW (USD) ──
B14: Dev Cost (phased 30/40/30%) | C14: Identical to Base — same physical asset. | D14: =-'6.3 Inputs'!$C$46*'6.3 Inputs'!$C$53 -> -12600000 | E14: =-'6.3 Inputs'!$C$47*'6.3 Inputs'!$C$53 -> -16800000 | F14: =-'6.3 Inputs'!$C$48*'6.3 Inputs'!$C$53 -> -12600000 | G14: 0 | H14: 0 | I14: 0 | J14: 0 | K14: 0 | L14: 0 | M14: 0 | N14: 0 | O14: 0 | P14: 0
B15: Pre-Opening (6.5% lump sum, Y2) | C15: Y2 lump-sum. | D15: 0 | E15: 0 | F15: =-'6.3 Inputs'!$C$54 -> -2730000 | G15: 0 | H15: 0 | I15: 0 | J15: 0 | K15: 0 | L15: 0 | M15: 0 | N15: 0 | O15: 0 | P15: 0
B16: Operating NOI (ramped — STRESS) | C16: Same ramp curve applied to STRESS NOI. | D16: 0 | E16: 0 | F16: 0 | G16: ='6.3.2 Rev-NOI'!$E$33*'6.3 Inputs'!$C$43 -> 1556965.6 | H16: ='6.3.2 Rev-NOI'!$E$33*'6.3 Inputs'!$C$44 -> 2242030.4 | I16: ='6.3.2 Rev-NOI'!$E$33*'6.3 Inputs'!$C$45 -> 2802538 | J16: ='6.3.2 Rev-NOI'!$E$33 -> 3113931.2 | K16: ='6.3.2 Rev-NOI'!$E$33*(1+'6.3 Inputs'!$C$30)^2 -> 3303569.6 | L16: ='6.3.2 Rev-NOI'!$E$33*(1+'6.3 Inputs'!$C$30)^3 -> 3402676.7 | M16: ='6.3.2 Rev-NOI'!$E$33*(1+'6.3 Inputs'!$C$30)^4 -> 3504757 | N16: ='6.3.2 Rev-NOI'!$E$33*(1+'6.3 Inputs'!$C$30)^5 -> 3609899.7 | O16: ='6.3.2 Rev-NOI'!$E$33*(1+'6.3 Inputs'!$C$30)^6 -> 3718196.7 | P16: ='6.3.2 Rev-NOI'!$E$33*(1+'6.3 Inputs'!$C$30)^7 -> 3829742.6
B17: Terminal Value (Gordon, Y12) | C17: TV based on Stress NOI Y12. | D17: 0 | E17: 0 | F17: 0 | G17: 0 | H17: 0 | I17: 0 | J17: 0 | K17: 0 | L17: 0 | M17: 0 | N17: 0 | O17: 0 | P17: =P16*(1+'6.3 Inputs'!$C$30)/'6.3 Inputs'!$C$29 -> 60686690
B18: NET CASH FLOW | C18: Sum of dev + pre-opening + NOI + TV. | D18: =SUM(D14:D17) -> -12600000 | E18: =SUM(E14:E17) -> -16800000 | F18: =SUM(F14:F17) -> -15330000 | G18: =SUM(G14:G17) -> 1556965.6 | H18: =SUM(H14:H17) -> 2242030.4 | I18: =SUM(I14:I17) -> 2802538 | J18: =SUM(J14:J17) -> 3113931.2 | K18: =SUM(K14:K17) -> 3303569.6 | ... P18: =SUM(P14:P17) -> 64516432
B20: ── IRR & NPV RESULTS ──
B21: Metric | C21: Formula | D21: Base Case | E21: Stress Case | F21: Investor Interpretation
B22: Unleveraged IRR (12-yr) | C22: IRR(D11:P11) → Base | IRR(D18:P18) → Stress | D22: =IRR(D11:P11) -> 0.13213278 | E22: =IRR(D18:P18) -> 0.079602159 | F22: Target band 8–12%. Base above band; Stress just below 8% floor (7.96%) — patient capital still backed by NPV@7% positive.
B23: NPV @ 7% — Patient Capital | C23: NPV at '6.3 Inputs'!$C$35 | D23: =D11+NPV('6.3 Inputs'!$C$35,E11:P11) -> 27509296 | E23: =D18+NPV('6.3 Inputs'!$C$35,E18:P18) -> 3555433.7 | F23: SWF / family office hurdle. Both must be positive.
B24: NPV @ 9% — Midpoint | C24: NPV at '6.3 Inputs'!$C$36 | D24: =D11+NPV('6.3 Inputs'!$C$36,E11:P11) -> 16438557 | E24: =D18+NPV('6.3 Inputs'!$C$36,E18:P18) -> -3414873.7 | F24: Midpoint of 8–12% IRR band.
B25: NPV @ 11% — Institutional PE | C25: NPV at '6.3 Inputs'!$C$37 | D25: =D11+NPV('6.3 Inputs'!$C$37,E11:P11) -> 7652968.7 | E25: =D18+NPV('6.3 Inputs'!$C$37,E18:P18) -> -8903665.2 | F25: Upper PE bound. Stress turns negative — NOT a PE deal.
B28: ── METHODOLOGY NOTES ──
B29: Construction phasing 30/40/30% | D29: Horwath HTL APAC Luxury Resort Development Timelines 2023. 3-year build for 35-key boutique luxury Pacific resort.
B30: Pre-opening cost 6.5% mid-case (5–8% range) | D30: HVS Hotel Pre-Opening Cost Benchmarks 2022; Horwath HTL Asia luxury openings. Boutique branded, 9-month programme.
B31: Operating ramp 50/72/90/100% | D31: HVS Hotel Investment Analysis 12th ed., 2021. Standard luxury resort ramp: Y3=50%, Y4=72%, Y5=90%, Y6+=stabilised.
B32: NOI growth 3.0% p.a. post-Y5 | D32: Horwath HTL APAC Resort Inflation Benchmarks. Conservative midpoint: between French Polynesia CPI (~2%) and luxury ADR growth (~4%).
B33: Cap rate 6.5% (entry & terminal) | D33: JLL APAC Hotel Investment Outlook 2024; Horwath HTL ultra-luxury comparables. Range 5.5–7.5%; midpoint applied. Conservative — assumes no terminal compression.
B34: Patient-capital hurdle: 7% | D34: SWF, family offices, long-hold institutional capital target 7–10% unleveraged IRR. Distinct from PE 11%+. Source: HVS, Horwath HTL APAC.
B35: 12-year hold horizon | D35: Spans two FM27-equivalent planning cycles and two territorial election cycles (Vaitape Strategic Report v6/v7 §6.3). Political-cycle insulation. Source: HVS Hotel Investment Analysis 12th ed., 2021.
B37: Source: HVS Hotel Investment Analysis 12th ed., 2021; HVS Hotel Pre-Opening Cost Benchmarks 2022; Horwath HTL APAC Hotel Trends 2024; JLL APAC Hotel Investment Outlook 2024; Vaitape Strategic Report v7 §6.3.

Sheet 6.4 ADR-Occ
B2: 6.4 ADR × Occupancy Sensitivity
B3: Two-way matrix: NOI (USD, left) and Development Yield (%, right) at varying ADR and Occupancy. Green ≥10% yield, Gold 8–10%, Red <8%.
B5: NOI (USD) | I5: Development Yield (NOI ÷ Build Cost)
B6: ADR \ Occ | C6: Occ 45% | D6: Occ 50% | E6: Occ 55% | F6: Occ 65% (Base) | G6: Occ 75% | I6: ADR \ Occ | J6: Occ 45% | K6: Occ 50% | L6: Occ 55% | M6: Occ 65% (Base) | N6: Occ 75%
B7: ADR −15% | C7: =('6.3 Inputs'!$C$11*0.85)*0.45*'6.3 Inputs'!$C$7*'6.3 Inputs'!$C$15*(1+'6.3 Inputs'!$C$13)*(1-'6.3 Inputs'!$C$20)-('6.3 Inputs'!$C$11*0.85)*0.45*'6.3 Inputs'!$C$7*'6.3 Inputs'!$C$15*(1+'6.3 Inputs'!$C$13)*'6.3 Inputs'!$C$21-(('6.3 Inputs'!$C$11*0.85)*0.45*'6.3 Inputs'!$C$7*'6.3 Inputs'!$C$15*(1+'6.3 Inputs'!$C$13)*(1-'6.3 Inputs'!$C$20))*'6.3 Inputs'!$C$22-('6.3 Inputs'!$C$11*0.85)*0.45*'6.3 Inputs'!$C$7*'6.3 Inputs'!$C$15*(1+'6.3 Inputs'!$C$13)*'6.3 Inputs'!$C$23 -> 2802538 | D7: =('6.3 Inputs'!$C$11*0.85)*0.5*'6.3 Inputs'!$C$7*'6.3 Inputs'!$C$15*(1+'6.3 Inputs'!$C$13)*(1-'6.3 Inputs'!$C$20)-('6.3 Inputs'!$C$11*0.85)*0.5*'6.3 Inputs'!$C$7*'6.3 Inputs'!$C$15*(1+'6.3 Inputs'!$C$13)*'6.3 Inputs'!$C$21-(('6.3 Inputs'!$C$11*0.85)*0.5*'6.3 Inputs'!$C$7*'6.3 Inputs'!$C$15*(1+'6.3 Inputs'!$C$13)*(1-'6.3 Inputs'!$C$20))*'6.3 Inputs'!$C$22-('6.3 Inputs'!$C$11*0.85)*0.5*'6.3 Inputs'!$C$7*'6.3 Inputs'!$C$15*(1+'6.3 Inputs'!$C$13)*'6.3 Inputs'!$C$23 -> 3113931.2 | E7: =('6.3 Inputs'!$C$11*0.85)*0.55*'6.3 Inputs'!$C$7*'6.3 Inputs'!$C$15*(1+'6.3 Inputs'!$C$13)*(1-'6.3 Inputs'!$C$20)-('6.3 Inputs'!$C$11*0.85)*0.55*'6.3 Inputs'!$C$7*'6.3 Inputs'!$C$15*(1+'6.3 Inputs'!$C$13)*'6.3 Inputs'!$C$21-(('6.3 Inputs'!$C$11*0.85)*0.55*'6.3 Inputs'!$C$7*'6.3 Inputs'!$C$15*(1+'6.3 Inputs'!$C$13)*(1-'6.3 Inputs'!$C$20))*'6.3 Inputs'!$C$22-('6.3 Inputs'!$C$11*0.85)*0.55*'6.3 Inputs'!$C$7*'6.3 Inputs'!$C$15*(1+'6.3 Inputs'!$C$13)*'6.3 Inputs'!$C$23 -> 3425324.3 | F7: =('6.3 Inputs'!$C$11*0.85)*0.65*'6.3 Inputs'!$C$7*'6.3 Inputs'!$C$15*(1+'6.3 Inputs'!$C$13)*(1-'6.3 Inputs'!$C$20)-('6.3 Inputs'!$C$11*0.85)*0.65*'6.3 Inputs'!$C$7*'6.3 Inputs'!$C$15*(1+'6.3 Inputs'!$C$13)*'6.3 Inputs'!$C$21-(('6.3 Inputs'!$C$11*0.85)*0.65*'6.3 Inputs'!$C$7*'6.3 Inputs'!$C$15*(1+'6.3 Inputs'!$C$13)*(1-'6.3 Inputs'!$C$20))*'6.3 Inputs'!$C$22-('6.3 Inputs'!$C$11*0.85)*0.65*'6.3 Inputs'!$C$7*'6.3 Inputs'!$C$15*(1+'6.3 Inputs'!$C$13)*'6.3 Inputs'!$C$23 -> 4048110.5 | G7: =('6.3 Inputs'!$C$11*0.85)*0.75*'6.3 Inputs'!$C$7*'6.3 Inputs'!$C$15*(1+'6.3 Inputs'!$C$13)*(1-'6.3 Inputs'!$C$20)-('6.3 Inputs'!$C$11*0.85)*0.75*'6.3 Inputs'!$C$7*'6.3 Inputs'!$C$15*(1+'6.3 Inputs'!$C$13)*'6.3 Inputs'!$C$21-(('6.3 Inputs'!$C$11*0.85)*0.75*'6.3 Inputs'!$C$7*'6.3 Inputs'!$C$15*(1+'6.3 Inputs'!$C$13)*(1-'6.3 Inputs'!$C$20))*'6.3 Inputs'!$C$22-('6.3 Inputs'!$C$11*0.85)*0.75*'6.3 Inputs'!$C$7*'6.3 Inputs'!$C$15*(1+'6.3 Inputs'!$C$13)*'6.3 Inputs'!$C$23 -> 4670896.7 | I7: ADR −15% | J7: =C7/'6.3 Inputs'!$C$53 -> 0.066727096 | K7: =D7/'6.3 Inputs'!$C$53 -> 0.074141218 | L7: =E7/'6.3 Inputs'!$C$53 -> 0.08155534 | M7: =F7/'6.3 Inputs'!$C$53 -> 0.096383584 | N7: =G7/'6.3 Inputs'!$C$53 -> 0.11121183
B8: ADR −10% | C8: =('6.3 Inputs'!$C$11*0.9)*0.45*'6.3 Inputs'!$C$7*'6.3 Inputs'!$C$15*(1+'6.3 Inputs'!$C$13)*(1-'6.3 Inputs'!$C$20)-('6.3 Inputs'!$C$11*0.9)*0.45*'6.3 Inputs'!$C$7*'6.3 Inputs'!$C$15*(1+'6.3 Inputs'!$C$13)*'6.3 Inputs'!$C$21-(('6.3 Inputs'!$C$11*0.9)*0.45*'6.3 Inputs'!$C$7*'6.3 Inputs'!$C$15*(1+'6.3 Inputs'!$C$13)*(1-'6.3 Inputs'!$C$20))*'6.3 Inputs'!$C$22-('6.3 Inputs'!$C$11*0.9)*0.45*'6.3 Inputs'!$C$7*'6.3 Inputs'!$C$15*(1+'6.3 Inputs'!$C$13)*'6.3 Inputs'!$C$23 -> 2967393.2 | D8: =('6.3 Inputs'!$C$11*0.9)*0.5*'6.3 Inputs'!$C$7*'6.3 Inputs'!$C$15*(1+'6.3 Inputs'!$C$13)*(1-'6.3 Inputs'!$C$20)-('6.3 Inputs'!$C$11*0.9)*0.5*'6.3 Inputs'!$C$7*'6.3 Inputs'!$C$15*(1+'6.3 Inputs'!$C$13)*'6.3 Inputs'!$C$21-(('6.3 Inputs'!$C$11*0.9)*0.5*'6.3 Inputs'!$C$7*'6.3 Inputs'!$C$15*(1+'6.3 Inputs'!$C$13)*(1-'6.3 Inputs'!$C$20))*'6.3 Inputs'!$C$22-('6.3 Inputs'!$C$11*0.9)*0.5*'6.3 Inputs'!$C$7*'6.3 Inputs'!$C$15*(1+'6.3 Inputs'!$C$13)*'6.3 Inputs'!$C$23 -> 3297103.6 | E8: =('6.3 Inputs'!$C$11*0.9)*0.55*'6.3 Inputs'!$C$7*'6.3 Inputs'!$C$15*(1+'6.3 Inputs'!$C$13)*(1-'6.3 Inputs'!$C$20)-('6.3 Inputs'!$C$11*0.9)*0.55*'6.3 Inputs'!$C$7*'6.3 Inputs'!$C$15*(1+'6.3 Inputs'!$C$13)*'6.3 Inputs'!$C$21-(('6.3 Inputs'!$C$11*0.9)*0.55*'6.3 Inputs'!$C$7*'6.3 Inputs'!$C$15*(1+'6.3 Inputs'!$C$13)*(1-'6.3 Inputs'!$C$20))*'6.3 Inputs'!$C$22-('6.3 Inputs'!$C$11*0.9)*0.55*'6.3 Inputs'!$C$7*'6.3 Inputs'!$C$15*(1+'6.3 Inputs'!$C$13)*'6.3 Inputs'!$C$23 -> 3626813.9 | F8: =('6.3 Inputs'!$C$11*0.9)*0.65*'6.3 Inputs'!$C$7*'6.3 Inputs'!$C$15*(1+'6.3 Inputs'!$C$13)*(1-'6.3 Inputs'!$C$20)-('6.3 Inputs'!$C$11*0.9)*0.65*'6.3 Inputs'!$C$7*'6.3 Inputs'!$C$15*(1+'6.3 Inputs'!$C$13)*'6.3 Inputs'!$C$21-(('6.3 Inputs'!$C$11*0.9)*0.65*'6.3 Inputs'!$C$7*'6.3 Inputs'!$C$15*(1+'6.3 Inputs'!$C$13)*(1-'6.3 Inputs'!$C$20))*'6.3 Inputs'!$C$22-('6.3 Inputs'!$C$11*0.9)*0.65*'6.3 Inputs'!$C$7*'6.3 Inputs'!$C$15*(1+'6.3 Inputs'!$C$13)*'6.3 Inputs'!$C$23 -> 4286234.7 | G8: =('6.3 Inputs'!$C$11*0.9)*0.75*'6.3 Inputs'!$C$7*'6.3 Inputs'!$C$15*(1+'6.3 Inputs'!$C$13)*(1-'6.3 Inputs'!$C$20)-('6.3 Inputs'!$C$11*0.9)*0.75*'6.3 Inputs'!$C$7*'6.3 Inputs'!$C$15*(1+'6.3 Inputs'!$C$13)*'6.3 Inputs'!$C$21-(('6.3 Inputs'!$C$11*0.9)*0.75*'6.3 Inputs'!$C$7*'6.3 Inputs'!$C$15*(1+'6.3 Inputs'!$C$13)*(1-'6.3 Inputs'!$C$20))*'6.3 Inputs'!$C$22-('6.3 Inputs'!$C$11*0.9)*0.75*'6.3 Inputs'!$C$7*'6.3 Inputs'!$C$15*(1+'6.3 Inputs'!$C$13)*'6.3 Inputs'!$C$23 -> 4945655.4 | I8: ADR −10% | J8: =C8/'6.3 Inputs'!$C$53 -> 0.07065222 | K8: =D8/'6.3 Inputs'!$C$53 -> 0.078502466 | L8: =E8/'6.3 Inputs'!$C$53 -> 0.086352713 | M8: =F8/'6.3 Inputs'!$C$53 -> 0.10205321 | N8: =G8/'6.3 Inputs'!$C$53 -> 0.1177537
B9: ADR Base | C9: =('6.3 Inputs'!$C$11)*0.45*'6.3 Inputs'!$C$7*'6.3 Inputs'!$C$15*(1+'6.3 Inputs'!$C$13)*(1-'6.3 Inputs'!$C$20)-('6.3 Inputs'!$C$11)*0.45*'6.3 Inputs'!$C$7*'6.3 Inputs'!$C$15*(1+'6.3 Inputs'!$C$13)*'6.3 Inputs'!$C$21-(('6.3 Inputs'!$C$11)*0.45*'6.3 Inputs'!$C$7*'6.3 Inputs'!$C$15*(1+'6.3 Inputs'!$C$13)*(1-'6.3 Inputs'!$C$20))*'6.3 Inputs'!$C$22-('6.3 Inputs'!$C$11)*0.45*'6.3 Inputs'!$C$7*'6.3 Inputs'!$C$15*(1+'6.3 Inputs'!$C$13)*'6.3 Inputs'!$C$23 -> 3297103.6 | D9: =('6.3 Inputs'!$C$11)*0.5*'6.3 Inputs'!$C$7*'6.3 Inputs'!$C$15*(1+'6.3 Inputs'!$C$13)*(1-'6.3 Inputs'!$C$20)-('6.3 Inputs'!$C$11)*0.5*'6.3 Inputs'!$C$7*'6.3 Inputs'!$C$15*(1+'6.3 Inputs'!$C$13)*'6.3 Inputs'!$C$21-(('6.3 Inputs'!$C$11)*0.5*'6.3 Inputs'!$C$7*'6.3 Inputs'!$C$15*(1+'6.3 Inputs'!$C$13)*(1-'6.3 Inputs'!$C$20))*'6.3 Inputs'!$C$22-('6.3 Inputs'!$C$11)*0.5*'6.3 Inputs'!$C$7*'6.3 Inputs'!$C$15*(1+'6.3 Inputs'!$C$13)*'6.3 Inputs'!$C$23 -> 3663448.4 | E9: =('6.3 Inputs'!$C$11)*0.55*'6.3 Inputs'!$C$7*'6.3 Inputs'!$C$15*(1+'6.3 Inputs'!$C$13)*(1-'6.3 Inputs'!$C$20)-('6.3 Inputs'!$C$11)*0.55*'6.3 Inputs'!$C$7*'6.3 Inputs'!$C$15*(1+'6.3 Inputs'!$C$13)*'6.3 Inputs'!$C$21-(('6.3 Inputs'!$C$11)*0.55*'6.3 Inputs'!$C$7*'6.3 Inputs'!$C$15*(1+'6.3 Inputs'!$C$13)*(1-'6.3 Inputs'!$C$20))*'6.3 Inputs'!$C$22-('6.3 Inputs'!$C$11)*0.55*'6.3 Inputs'!$C$7*'6.3 Inputs'!$C$15*(1+'6.3 Inputs'!$C$13)*'6.3 Inputs'!$C$23 -> 4029793.3 | F9: =('6.3 Inputs'!$C$11)*0.65*'6.3 Inputs'!$C$7*'6.3 Inputs'!$C$15*(1+'6.3 Inputs'!$C$13)*(1-'6.3 Inputs'!$C$20)-('6.3 Inputs'!$C$11)*0.65*'6.3 Inputs'!$C$7*'6.3 Inputs'!$C$15*(1+'6.3 Inputs'!$C$13)*'6.3 Inputs'!$C$21-(('6.3 Inputs'!$C$11)*0.65*'6.3 Inputs'!$C$7*'6.3 Inputs'!$C$15*(1+'6.3 Inputs'!$C$13)*(1-'6.3 Inputs'!$C$20))*'6.3 Inputs'!$C$22-('6.3 Inputs'!$C$11)*0.65*'6.3 Inputs'!$C$7*'6.3 Inputs'!$C$15*(1+'6.3 Inputs'!$C$13)*'6.3 Inputs'!$C$23 -> 4762483 | G9: =('6.3 Inputs'!$C$11)*0.75*'6.3 Inputs'!$C$7*'6.3 Inputs'!$C$15*(1+'6.3 Inputs'!$C$13)*(1-'6.3 Inputs'!$C$20)-('6.3 Inputs'!$C$11)*0.75*'6.3 Inputs'!$C$7*'6.3 Inputs'!$C$15*(1+'6.3 Inputs'!$C$13)*'6.3 Inputs'!$C$21-(('6.3 Inputs'!$C$11)*0.75*'6.3 Inputs'!$C$7*'6.3 Inputs'!$C$15*(1+'6.3 Inputs'!$C$13)*(1-'6.3 Inputs'!$C$20))*'6.3 Inputs'!$C$22-('6.3 Inputs'!$C$11)*0.75*'6.3 Inputs'!$C$7*'6.3 Inputs'!$C$15*(1+'6.3 Inputs'!$C$13)*'6.3 Inputs'!$C$23 -> 5495172.6 | I9: ADR Base | J9: =C9/'6.3 Inputs'!$C$53 -> 0.078502466 | K9: =D9/'6.3 Inputs'!$C$53 -> 0.087224963 | L9: =E9/'6.3 Inputs'!$C$53 -> 0.095947459 | M9: =F9/'6.3 Inputs'!$C$53 -> 0.11339245 | N9: =G9/'6.3 Inputs'!$C$53 -> 0.13083744
B10: ADR +10% | C10: =('6.3 Inputs'!$C$11*1.1)*0.45*'6.3 Inputs'!$C$7*'6.3 Inputs'!$C$15*(1+'6.3 Inputs'!$C$13)*(1-'6.3 Inputs'!$C$20)-('6.3 Inputs'!$C$11*1.1)*0.45*'6.3 Inputs'!$C$7*'6.3 Inputs'!$C$15*(1+'6.3 Inputs'!$C$13)*'6.3 Inputs'!$C$21-(('6.3 Inputs'!$C$11*1.1)*0.45*'6.3 Inputs'!$C$7*'6.3 Inputs'!$C$15*(1+'6.3 Inputs'!$C$13)*(1-'6.3 Inputs'!$C$20))*'6.3 Inputs'!$C$22-('6.3 Inputs'!$C$11*1.1)*0.45*'6.3 Inputs'!$C$7*'6.3 Inputs'!$C$15*(1+'6.3 Inputs'!$C$13)*'6.3 Inputs'!$C$23 -> 3626813.9 | D10: =('6.3 Inputs'!$C$11*1.1)*0.5*'6.3 Inputs'!$C$7*'6.3 Inputs'!$C$15*(1+'6.3 Inputs'!$C$13)*(1-'6.3 Inputs'!$C$20)-('6.3 Inputs'!$C$11*1.1)*0.5*'6.3 Inputs'!$C$7*'6.3 Inputs'!$C$15*(1+'6.3 Inputs'!$C$13)*'6.3 Inputs'!$C$21-(('6.3 Inputs'!$C$11*1.1)*0.5*'6.3 Inputs'!$C$7*'6.3 Inputs'!$C$15*(1+'6.3 Inputs'!$C$13)*(1-'6.3 Inputs'!$C$20))*'6.3 Inputs'!$C$22-('6.3 Inputs'!$C$11*1.1)*0.5*'6.3 Inputs'!$C$7*'6.3 Inputs'!$C$15*(1+'6.3 Inputs'!$C$13)*'6.3 Inputs'!$C$23 -> 4029793.3 | E10: =('6.3 Inputs'!$C$11*1.1)*0.55*'6.3 Inputs'!$C$7*'6.3 Inputs'!$C$15*(1+'6.3 Inputs'!$C$13)*(1-'6.3 Inputs'!$C$20)-('6.3 Inputs'!$C$11*1.1)*0.55*'6.3 Inputs'!$C$7*'6.3 Inputs'!$C$15*(1+'6.3 Inputs'!$C$13)*'6.3 Inputs'!$C$21-(('6.3 Inputs'!$C$11*1.1)*0.55*'6.3 Inputs'!$C$7*'6.3 Inputs'!$C$15*(1+'6.3 Inputs'!$C$13)*(1-'6.3 Inputs'!$C$20))*'6.3 Inputs'!$C$22-('6.3 Inputs'!$C$11*1.1)*0.55*'6.3 Inputs'!$C$7*'6.3 Inputs'!$C$15*(1+'6.3 Inputs'!$C$13)*'6.3 Inputs'!$C$23 -> 4432772.6 | F10: =('6.3 Inputs'!$C$11*1.1)*0.65*'6.3 Inputs'!$C$7*'6.3 Inputs'!$C$15*(1+'6.3 Inputs'!$C$13)*(1-'6.3 Inputs'!$C$20)-('6.3 Inputs'!$C$11*1.1)*0.65*'6.3 Inputs'!$C$7*'6.3 Inputs'!$C$15*(1+'6.3 Inputs'!$C$13)*'6.3 Inputs'!$C$21-(('6.3 Inputs'!$C$11*1.1)*0.65*'6.3 Inputs'!$C$7*'6.3 Inputs'!$C$15*(1+'6.3 Inputs'!$C$13)*(1-'6.3 Inputs'!$C$20))*'6.3 Inputs'!$C$22-('6.3 Inputs'!$C$11*1.1)*0.65*'6.3 Inputs'!$C$7*'6.3 Inputs'!$C$15*(1+'6.3 Inputs'!$C$13)*'6.3 Inputs'!$C$23 -> 5238731.2 | G10: =('6.3 Inputs'!$C$11*1.1)*0.75*'6.3 Inputs'!$C$7*'6.3 Inputs'!$C$15*(1+'6.3 Inputs'!$C$13)*(1-'6.3 Inputs'!$C$20)-('6.3 Inputs'!$C$11*1.1)*0.75*'6.3 Inputs'!$C$7*'6.3 Inputs'!$C$15*(1+'6.3 Inputs'!$C$13)*'6.3 Inputs'!$C$21-(('6.3 Inputs'!$C$11*1.1)*0.75*'6.3 Inputs'!$C$7*'6.3 Inputs'!$C$15*(1+'6.3 Inputs'!$C$13)*(1-'6.3 Inputs'!$C$20))*'6.3 Inputs'!$C$22-('6.3 Inputs'!$C$11*1.1)*0.75*'6.3 Inputs'!$C$7*'6.3 Inputs'!$C$15*(1+'6.3 Inputs'!$C$13)*'6.3 Inputs'!$C$23 -> 6044689.9 | I10: ADR +10% | J10: =C10/'6.3 Inputs'!$C$53 -> 0.086352713 | K10: =D10/'6.3 Inputs'!$C$53 -> 0.095947459 | L10: =E10/'6.3 Inputs'!$C$53 -> 0.1055422 | M10: =F10/'6.3 Inputs'!$C$53 -> 0.1247317 | N10: =G10/'6.3 Inputs'!$C$53 -> 0.14392119
B11: ADR +15% | C11: =('6.3 Inputs'!$C$11*1.15)*0.45*'6.3 Inputs'!$C$7*'6.3 Inputs'!$C$15*(1+'6.3 Inputs'!$C$13)*(1-'6.3 Inputs'!$C$20)-('6.3 Inputs'!$C$11*1.15)*0.45*'6.3 Inputs'!$C$7*'6.3 Inputs'!$C$15*(1+'6.3 Inputs'!$C$13)*'6.3 Inputs'!$C$21-(('6.3 Inputs'!$C$11*1.15)*0.45*'6.3 Inputs'!$C$7*'6.3 Inputs'!$C$15*(1+'6.3 Inputs'!$C$13)*(1-'6.3 Inputs'!$C$20))*'6.3 Inputs'!$C$22-('6.3 Inputs'!$C$11*1.15)*0.45*'6.3 Inputs'!$C$7*'6.3 Inputs'!$C$15*(1+'6.3 Inputs'!$C$13)*'6.3 Inputs'!$C$23 -> 3791669.1 | D11: =('6.3 Inputs'!$C$11*1.15)*0.5*'6.3 Inputs'!$C$7*'6.3 Inputs'!$C$15*(1+'6.3 Inputs'!$C$13)*(1-'6.3 Inputs'!$C$20)-('6.3 Inputs'!$C$11*1.15)*0.5*'6.3 Inputs'!$C$7*'6.3 Inputs'!$C$15*(1+'6.3 Inputs'!$C$13)*'6.3 Inputs'!$C$21-(('6.3 Inputs'!$C$11*1.15)*0.5*'6.3 Inputs'!$C$7*'6.3 Inputs'!$C$15*(1+'6.3 Inputs'!$C$13)*(1-'6.3 Inputs'!$C$20))*'6.3 Inputs'!$C$22-('6.3 Inputs'!$C$11*1.15)*0.5*'6.3 Inputs'!$C$7*'6.3 Inputs'!$C$15*(1+'6.3 Inputs'!$C$13)*'6.3 Inputs'!$C$23 -> 4212965.7 | E11: =('6.3 Inputs'!$C$11*1.15)*0.55*'6.3 Inputs'!$C$7*'6.3 Inputs'!$C$15*(1+'6.3 Inputs'!$C$13)*(1-'6.3 Inputs'!$C$20)-('6.3 Inputs'!$C$11*1.15)*0.55*'6.3 Inputs'!$C$7*'6.3 Inputs'!$C$15*(1+'6.3 Inputs'!$C$13)*'6.3 Inputs'!$C$21-(('6.3 Inputs'!$C$11*1.15)*0.55*'6.3 Inputs'!$C$7*'6.3 Inputs'!$C$15*(1+'6.3 Inputs'!$C$13)*(1-'6.3 Inputs'!$C$20))*'6.3 Inputs'!$C$22-('6.3 Inputs'!$C$11*1.15)*0.55*'6.3 Inputs'!$C$7*'6.3 Inputs'!$C$15*(1+'6.3 Inputs'!$C$13)*'6.3 Inputs'!$C$23 -> 4634262.3 | F11: =('6.3 Inputs'!$C$11*1.15)*0.65*'6.3 Inputs'!$C$7*'6.3 Inputs'!$C$15*(1+'6.3 Inputs'!$C$13)*(1-'6.3 Inputs'!$C$20)-('6.3 Inputs'!$C$11*1.15)*0.65*'6.3 Inputs'!$C$7*'6.3 Inputs'!$C$15*(1+'6.3 Inputs'!$C$13)*'6.3 Inputs'!$C$21-(('6.3 Inputs'!$C$11*1.15)*0.65*'6.3 Inputs'!$C$7*'6.3 Inputs'!$C$15*(1+'6.3 Inputs'!$C$13)*(1-'6.3 Inputs'!$C$20))*'6.3 Inputs'!$C$22-('6.3 Inputs'!$C$11*1.15)*0.65*'6.3 Inputs'!$C$7*'6.3 Inputs'!$C$15*(1+'6.3 Inputs'!$C$13)*'6.3 Inputs'!$C$23 -> 5476855.4 | G11: =('6.3 Inputs'!$C$11*1.15)*0.75*'6.3 Inputs'!$C$7*'6.3 Inputs'!$C$15*(1+'6.3 Inputs'!$C$13)*(1-'6.3 Inputs'!$C$20)-('6.3 Inputs'!$C$11*1.15)*0.75*'6.3 Inputs'!$C$7*'6.3 Inputs'!$C$15*(1+'6.3 Inputs'!$C$13)*'6.3 Inputs'!$C$21-(('6.3 Inputs'!$C$11*1.15)*0.75*'6.3 Inputs'!$C$7*'6.3 Inputs'!$C$15*(1+'6.3 Inputs'!$C$13)*(1-'6.3 Inputs'!$C$20))*'6.3 Inputs'!$C$22-('6.3 Inputs'!$C$11*1.15)*0.75*'6.3 Inputs'!$C$7*'6.3 Inputs'!$C$15*(1+'6.3 Inputs'!$C$13)*'6.3 Inputs'!$C$23 -> 6319448.5 | I11: ADR +15% | J11: =C11/'6.3 Inputs'!$C$53 -> 0.090277836 | K11: =D11/'6.3 Inputs'!$C$53 -> 0.10030871 | L11: =E11/'6.3 Inputs'!$C$53 -> 0.11033958 | M11: =F11/'6.3 Inputs'!$C$53 -> 0.13040132 | N11: =G11/'6.3 Inputs'!$C$53 -> 0.15046306
B13: Investor insight
B14: Base case (ADR $2,150 × Occ 65%) sits at 11.3% development yield — comfortably green. The asset stays investable (gold 8–10%) even at ADR −15% × Occ 55%. The matrix collapses into red only at ADR −15% × Occ ≤45% (cyclone + pricing collapse simultaneously). This is the structural cushion patient capital is paying for.
B16: ── COLOUR LEGEND & INVESTOR INTERPRETATION ──
B17: GREEN | C17: Dev yield ≥ 10% — target exceeded. Strong value-creation across cap-rate range.
B18: GOLD | C18: Dev yield 8–10% — investable for patient capital. Within 8–12% IRR band; clears yield-on-cost floor.
B19: RED | C19: Dev yield < 8% — below patient-capital floor. Asset value < build cost; project loses value vs sunk capital.
B21: Formula: NOI = [ADR × Occupancy × (1 + 35% TRevPAR) × 35 keys × 365] × (1 − 72% OpCost) − Mgmt Fees − FF&E Reserve. Dev Yield = NOI ÷ $42M development cost. The matrix shows 25 ADR×Occupancy permutations: ADR ±15% on Base $2,150; Occupancy 45–75% in 5pp steps. Even at 45% occupancy with Base ADR, dev yield clears the 8% patient-capital floor in most cells — confirming downside resilience.
B23: Source: HVS Hotel Investment Analysis 12th ed., 2021; STR Global ultra-luxury benchmarks; JLL APAC Hotel Investment Outlook 2024.

Sheet C.7 Independence
B2: C.7 Independence Flag — TRevPAR Benchmark
B3: RICS Red Book Global Standards 2022 (VPS3) requires independence between the benchmark producer and the project being valued. KPMG 2025 fails this test.
B5: Item | C5: Status / Value | D5: Detail
B6: KPMG TRevPAR Premium (2025) | C6: EXCLUDED | D6: Polynesia Consulting (principal Henry Terou) co-authored the KPMG benchmark report and simultaneously serves as local project representative for the Surbana Jurong engagement of which this study forms part. Per RICS Red Book independence standards, this is a connected-party relationship.
B7: KPMG figure (reference only) | C7: 65% | D7: Reported in KPMG Tourist Accommodation French Polynesia Part 1 p.83. NOT applied in any base or stress calculation.
B8: Independent triangulated figure | C8: 35% | D8: STR Global ultra-luxury non-room uplift; HVS Performance Report 2019 boutique resort F&B + Spa benchmarks. Used throughout the model.
B9: Effect on verdict | C9: NONE | D9: All Section 6 conclusions hold on the 35% independent figure alone. The 65% figure is preserved only as upside disclosure in C.7 and is NOT in any IRR / NPV / asset-value computation.
B10: Next-stage action | C10: Independent benchmarking | D10: Investor due diligence team should commission a non-connected non-room revenue benchmarking exercise. Recommended providers: STR Global, HVS, Horwath HTL — none of which have a contractual relationship with the project sponsor or Surbana Jurong.
B12: ── RICS Red Book Long-Form Independence Statement (from v3) ──
B13: Per RICS Red Book Global Standards 2022 (VPS3 / VPS5), the valuer must declare independence between the benchmark inputs used and any party with a financial interest in the project outcome. Polynesia Consulting (principal: Mr Henry Terou) co-authored the KPMG Tourist Accommodation French Polynesia report (2025), and is also the sponsoring consultancy on the Vaitape ultra-luxury hotel mandate. This dual-role connection means KPMG's reported 65% TRevPAR premium for ultra-luxury Polynesian properties (KPMG Part 1 p.83) cannot be relied upon as an independent benchmark in the feasibility model. Mitigation applied: the model substitutes a CONSERVATIVE 35% non-room revenue uplift, triangulated from (a) STR Global Luxury & Ultra-Luxury ADR & TRevPAR Benchmarks (subscription, institutional access); (b) HVS Performance Report — Spa Department for Boutique Ultra-Luxury Resorts (2019); and (c) HVS Hotel Investment Analysis 12th ed. (2021) sectoral guidance for boutique ultra-luxury Pacific and Indian-Ocean comparables. All headline conclusions in §6.2 hold on the 35% figure alone — including Gate 1 (asset value > build cost), Gate 2 (IRR within 8–12% patient-capital band, NPV @ 7% > 0), and Gate 3 (yield-on-cost spread ≥ 100 bps). The 65% KPMG figure, were it independently corroborated, would represent additional upside not currently relied upon. Recommended next-stage action: investor due-diligence team should commission a non-connected non-room revenue benchmark — e.g. STR/CBRE ad-hoc benchmark study, or Horwath HTL APAC custom comparable set — before financial close. RICS Red Book VPS3 §3.4 documentation requirement: this statement is appended to all valuation outputs and the related model worksheet.
B15: Source: RICS Red Book Global Standards 2022 (VPS3 / VPS5); KPMG Tourist Accommodation French Polynesia 2025 Part 1 p.83 (reference only); STR Global Luxury Benchmarks; HVS Performance Report Spa Dept 2019; HVS Hotel Investment Analysis 12th ed., 2021.

Sheet C.8 Defisc
B2: C.8 Defisc (LODEOM) — Upside Lever, NOT Base Case
B3: Investability is demonstrated on construction cost alone in §6.2. Defisc treated here as quantified upside — confirms the deal is robust to political risk on tax-credit access.
B5: Item | C5: Pre-Defisc | D5: Post-Defisc | E5: Note
B6: Defisc Credit Rate | D6: ='6.3 Inputs'!$C$39 -> 0.25 | E6: 25% on qualifying expenditure for Bora Bora priority island.
B7: Defisc Cap (XPF) | D7: ='6.3 Inputs'!$C$40 -> 500000000 | E7: Maximum qualifying investment XPF 500M.
B8: XPF/USD FX | D8: ='6.3 Inputs'!$C$41 -> 119.5 | E8: Indicative — confirm with Polynesian counsel.
B9: Defisc Cap (USD) | D9: ='6.3 Inputs'!$C$56 -> 4184100.4 | E9: Cap binds because 25% × $42M ($10.5M) > $4.18M cap.
B10: Theoretical credit (uncapped) | D10: ='6.3 Inputs'!$C$57 -> 10500000 | E10: What the rate would deliver absent cap.
B11: Effective credit (capped) | D11: ='6.3 Inputs'!$C$58 -> 4184100.4 | E11: Actual amount applied — $4.18M.
B12: Total Development Cost | C12: ='6.3 Inputs'!$C$53 -> 42000000 | D12: ='6.3 Inputs'!$C$53-'6.3 Inputs'!$C$58 -> 37815900 | E12: Dev cost less effective credit.
B13: Stabilised NOI — Base | C13: ='6.3.2 Rev-NOI'!$C$33 -> 4762483 | D13: ='6.3.2 Rev-NOI'!$C$33 -> 4762483 | E13: NOI unchanged — Defisc affects denominator only.
